<sdf version='1.6'>
  <world name='default'>
    <light name='sun' type='directional'>
      <cast_shadows>1</cast_shadows>
      <pose frame=''>0 0 10 0 -0 0</pose>
      <diffuse>0.8 0.8 0.8 1</diffuse>
      <specular>0.2 0.2 0.2 1</specular>
      <attenuation>
        <range>1000</range>
        <constant>0.9</constant>
        <linear>0.01</linear>
        <quadratic>0.001</quadratic>
      </attenuation>
      <direction>-0.5 0.1 -0.9</direction>
    </light>
    <model name='ground_plane'>
      <static>1</static>
      <link name='link'>
        <collision name='collision'>
          <geometry>
            <plane>
              <normal>0 0 1</normal>
              <size>100 100</size>
            </plane>
          </geometry>
          <surface>
            <contact>
              <collide_bitmask>65535</collide_bitmask>
              <ode/>
            </contact>
            <friction>
              <ode>
                <mu>100</mu>
                <mu2>50</mu2>
              </ode>
              <torsional>
                <ode/>
              </torsional>
            </friction>
            <bounce/>
          </surface>
          <max_contacts>10</max_contacts>
        </collision>
        <visual name='visual'>
          <cast_shadows>0</cast_shadows>
          <geometry>
            <plane>
              <normal>0 0 1</normal>
              <size>100 100</size>
            </plane>
          </geometry>
          <material>
            <script>
              <uri>file://media/materials/scripts/gazebo.material</uri>
              <name>Gazebo/Grey</name>
            </script>
          </material>
        </visual>
        <self_collide>0</self_collide>
        <enable_wind>0</enable_wind>
        <kinematic>0</kinematic>
      </link>
    </model>
    <gravity>0 0 -9.8</gravity>
    <magnetic_field>6e-06 2.3e-05 -4.2e-05</magnetic_field>
    <atmosphere type='adiabatic'/>
    <physics name='default_physics' default='0' type='ode'>
      <max_step_size>0.001</max_step_size>
      <real_time_factor>1</real_time_factor>
      <real_time_update_rate>1000</real_time_update_rate>
    </physics>
    <scene>
      <ambient>0.4 0.4 0.4 1</ambient>
      <background>0.7 0.7 0.7 1</background>
      <shadows>1</shadows>
    </scene>
    <audio>
      <device>default</device>
    </audio>
    <wind/>
    <spherical_coordinates>
      <surface_model>EARTH_WGS84</surface_model>
      <latitude_deg>0</latitude_deg>
      <longitude_deg>0</longitude_deg>
      <elevation>0</elevation>
      <heading_deg>0</heading_deg>
    </spherical_coordinates>
    <state world_name='default'>
      <sim_time>521 43000000</sim_time>
      <real_time>557 257756909</real_time>
      <wall_time>1605671726 121371175</wall_time>
      <iterations>521043</iterations>
      <model name='drc_practice_organge_jersey_barrier'>
        <pose frame=''>3.9268 1.41958 0 0 -0 0</pose>
        <scale>1 1 1</scale>
        <link name='link'>
          <pose frame=''>3.9268 1.41958 0 0 -0 0</pose>
          <velocity>0 0 0 0 -0 0</velocity>
          <acceleration>0 0 0 0 -0 0</acceleration>
          <wrench>0 0 0 0 -0 0</wrench>
        </link>
      </model>
      <model name='frc2016_moat'>
        <pose frame=''>8.06891 -1.33573 0 0 -0 0</pose>
        <scale>1 1 1</scale>
        <link name='link'>
          <pose frame=''>8.06891 -1.33573 0 0 -0 0</pose>
          <velocity>0 0 0 0 -0 0</velocity>
          <acceleration>0 0 0 0 -0 0</acceleration>
          <wrench>0 0 0 0 -0 0</wrench>
        </link>
      </model>
      <model name='frc2016_portcullis'>
        <pose frame=''>2.36019 -4.66378 1e-06 -1e-06 -2e-06 0.038961</pose>
        <scale>1 1 1</scale>
        <link name='base'>
          <pose frame=''>2.36019 -4.66378 1e-06 -1e-06 -2e-06 0.038961</pose>
          <velocity>1.1e-05 -0.000232 0.002142 -0.00129 0.000943 -0.000549</velocity>
          <acceleration>4.31322 0.25959 3.7551 2.7494 -1.02545 2.50752</acceleration>
          <wrench>215.661 12.9795 187.755 0 -0 0</wrench>
        </link>
        <link name='gate'>
          <pose frame=''>2.33039 -4.63607 0.933271 -1e-06 -3e-06 0.038961</pose>
          <velocity>0.000894 0.000971 0.002136 -0.001452 0.001059 -0.001027</velocity>
          <acceleration>3.92868 0.219742 3.86802 2.59567 -1.08133 2.0961</acceleration>
          <wrench>7.85736 0.439485 7.73605 0 -0 0</wrench>
        </link>
      </model>
      <model name='ground_plane'>
        <pose frame=''>0 0 0 0 -0 0</pose>
        <scale>1 1 1</scale>
        <link name='link'>
          <pose frame=''>0 0 0 0 -0 0</pose>
          <velocity>0 0 0 0 -0 0</velocity>
          <acceleration>0 0 0 0 -0 0</acceleration>
          <wrench>0 0 0 0 -0 0</wrench>
        </link>
      </model>
      <model name='polaris_ranger_ev'>
        <pose frame=''>-3.46161 -2.20052 0.00027 -9.1e-05 6.2e-05 -0.002807</pose>
        <scale>1 1 1</scale>
        <link name='FNR_switch'>
          <pose frame=''>-2.9016 -2.22199 1.08024 -9.2e-05 0.071311 -0.002814</pose>
          <velocity>-0.001282 -0.003464 -0.006009 0.004433 -0.001785 -0.000283</velocity>
          <acceleration>-1.4e-05 0 -1e-06 -0 3e-06 -8e-06</acceleration>
          <wrench>-1e-06 0 -0 0 -0 0</wrench>
        </link>
        <link name='brake_pedal'>
          <pose frame=''>-2.75222 -1.93246 0.539042 -9.2e-05 6.4e-05 -0.002807</pose>
          <velocity>-0.000238 -0.001107 -0.004442 0.004478 -0.001901 -0.000285</velocity>
          <acceleration>-1.5e-05 0 -1e-06 0 -0 0</acceleration>
          <wrench>-1e-06 0 -0 0 -0 0</wrench>
        </link>
        <link name='chassis'>
          <pose frame=''>-3.46161 -2.20052 0.00027 -9.1e-05 6.2e-05 -0.002807</pose>
          <velocity>0.000662 0.001459 -0.006933 0.004391 -0.001785 -0.00028</velocity>
          <acceleration>-1.5e-05 0 -0 0 -0 6e-06</acceleration>
          <wrench>-0.01059 9.6e-05 -0.000294 0 -0 0</wrench>
        </link>
        <link name='front_left_wheel'>
          <pose frame=''>-2.42757 -1.60342 0.320233 1.49912 -0.812219 -3.1151</pose>
          <velocity>0.000264 -0.000869 -0.011055 0.004413 0.000759 -2.2e-05</velocity>
          <acceleration>-1.5e-05 0 -1e-06 0 -2.4e-05 -2e-06</acceleration>
          <wrench>-0.000182 1e-06 -1.6e-05 0 -0 0</wrench>
        </link>
        <link name='front_left_wheel_steering_block'>
          <pose frame=''>-2.43019 -1.70338 0.320265 1.57071 6e-05 -0.026182</pose>
          <velocity>0.000254 -0.000879 -0.013916 0.004084 -0.001773 -0.000163</velocity>
          <acceleration>-1.5e-05 0 -2e-06 0 1e-06 1e-06</acceleration>
          <wrench>-1.5e-05 0 -2e-06 0 -0 0</wrench>
        </link>
        <link name='front_right_wheel'>
          <pose frame=''>-2.43429 -2.80337 0.320279 -1.49953 -0.803375 3.07676</pose>
          <velocity>-9.8e-05 -0.001107 -0.00618 0.002516 -0.000144 -0.000476</velocity>
          <acceleration>-1.5e-05 0 -1e-06 -0 -2.3e-05 2e-06</acceleration>
          <wrench>-0.000182 1e-06 -1.5e-05 0 -0 0</wrench>
        </link>
        <link name='front_right_wheel_steering_block'>
          <pose frame=''>-2.433 -2.70338 0.320275 1.57071 6.1e-05 -0.012895</pose>
          <velocity>-5.8e-05 -0.00111 -0.005306 0.004153 -0.001801 -0.000394</velocity>
          <acceleration>-1.5e-05 0 -1e-06 0 1e-06 -1e-06</acceleration>
          <wrench>-1.5e-05 0 -1e-06 0 -0 0</wrench>
        </link>
        <link name='gas_pedal'>
          <pose frame=''>-2.77473 -2.1024 0.52365 -9.2e-05 6.3e-05 -0.002807</pose>
          <velocity>-0.000257 -0.001032 -0.005245 0.004446 -0.001877 -0.000283</velocity>
          <acceleration>-1.5e-05 0 -1e-06 0 -0 0</acceleration>
          <wrench>-1e-06 0 -0 0 -0 0</wrench>
        </link>
        <link name='hand_brake'>
          <pose frame=''>-2.93135 -2.13191 1.05023 -9.3e-05 -0.178513 -0.002791</pose>
          <velocity>-0.001203 -0.003322 -0.005663 0.004434 -0.001785 -0.000285</velocity>
          <acceleration>-1.4e-05 0 -1e-06 1e-06 3e-06 -0</acceleration>
          <wrench>-7e-06 0 -0 0 -0 0</wrench>
        </link>
        <link name='rear_left_wheel'>
          <pose frame=''>-4.3099 -1.5981 0.320267 1.49909 -0.812041 -3.09171</pose>
          <velocity>0.000267 -8.7e-05 -0.00561 0.001105 0.000779 -0.000126</velocity>
          <acceleration>-1.5e-05 0 0 -6.2e-05 -0.028021 -0.013854</acceleration>
          <wrench>-0.000178 0 1e-06 0 -0 0</wrench>
        </link>
        <link name='rear_right_wheel'>
          <pose frame=''>-4.31333 -2.79811 0.320237 -1.49957 -0.803135 3.08689</pose>
          <velocity>-7.9e-05 -0.000293 -0.011151 -0.000803 -0.000125 -0.000364</velocity>
          <acceleration>-1.5e-05 0 -0 9.8e-05 0.028688 0.005433</acceleration>
          <wrench>-0.000176 0 -1e-06 0 -0 0</wrench>
        </link>
        <link name='steering_wheel'>
          <pose frame=''>-3.1207 -1.90164 1.29021 0.164082 -0.858394 -0.21827</pose>
          <velocity>-0.00157 -0.004333 -0.004983 0.004408 -0.0018 -0.000261</velocity>
          <acceleration>-1.4e-05 -0 -0 -3e-06 -9e-06 -1e-06</acceleration>
          <wrench>-1.4e-05 -0 -0 0 -0 0</wrench>
        </link>
      </model>
      <model name='prius_hybrid_sensors'>
        <pose frame=''>-6.28914 8.79926 -0.018359 -2e-06 0 0.001532</pose>
        <scale>1 1 1</scale>
        <link name='prius_hybrid::chassis'>
          <pose frame=''>-6.28914 8.79926 0.011641 -2e-06 0 0.001532</pose>
          <velocity>3.1e-05 -7e-06 2.1e-05 -3e-06 -0 2e-05</velocity>
          <acceleration>-0 0 -0 0 -0 0</acceleration>
          <wrench>-5e-05 1.1e-05 -0 0 -0 0</wrench>
        </link>
        <link name='prius_hybrid::front_left_wheel'>
          <pose frame=''>-5.52698 7.39043 0.311646 -0.001272 0.014366 0.166492</pose>
          <velocity>5.9e-05 1e-05 3.2e-05 -3.3e-05 0.000189 0.002243</velocity>
          <acceleration>-0 -0 -0 0 -0 -2e-06</acceleration>
          <wrench>-1e-06 -0 -0 0 -0 0</wrench>
        </link>
        <link name='prius_hybrid::front_right_wheel'>
          <pose frame=''>-7.04698 7.3881 0.311646 0.005941 0.013715 0.158941</pose>
          <velocity>5.9e-05 -2e-05 3.2e-05 6.4e-05 0.000188 0.002049</velocity>
          <acceleration>-0 0 -0 -0 -0 -4e-06</acceleration>
          <wrench>-1e-06 0 -0 0 -0 0</wrench>
        </link>
        <link name='prius_hybrid::rear_axle'>
          <pose frame=''>-6.29136 10.2493 0.311642 -4e-06 -5e-06 0.001532</pose>
          <velocity>1e-06 -6e-06 2e-05 1e-06 -4e-06 2e-05</velocity>
          <acceleration>0 0 -0 -0.001902 -3e-06 -0</acceleration>
          <wrench>0 0 -0 0 -0 0</wrench>
        </link>
        <link name='prius_hybrid::rear_left_wheel'>
          <pose frame=''>-5.50536 10.2505 0.311647 -0.002527 -3e-06 0.001532</pose>
          <velocity>1e-06 1e-05 2.5e-05 -3.2e-05 -1e-06 2e-05</velocity>
          <acceleration>-0 -0 -0 0 -0 0</acceleration>
          <wrench>-0 -0 -0 0 -0 0</wrench>
        </link>
        <link name='prius_hybrid::rear_right_wheel'>
          <pose frame=''>-7.07736 10.2481 0.311647 0.005308 9e-06 0.001532</pose>
          <velocity>2e-06 -2.1e-05 2.5e-05 7.1e-05 2e-06 2e-05</velocity>
          <acceleration>0 0 0 0 -0 0</acceleration>
          <wrench>0 0 0 0 -0 0</wrench>
        </link>
        <link name='prius_hybrid::steering_wheel'>
          <pose frame=''>-5.9315 8.17241 0.998181 -1.04205 1.01649 0.462655</pose>
          <velocity>2.8e-05 6e-06 1.4e-05 -1.6e-05 0.008605 0.002391</velocity>
          <acceleration>0 -0 0 -1.8e-05 0.011191 0.000379</acceleration>
          <wrench>0 -0 0 0 -0 0</wrench>
        </link>
        <link name='sensors'>
          <pose frame=''>-6.28914 8.79926 -0.018359 -2e-06 0 0.001532</pose>
          <velocity>3.1e-05 -7e-06 2.1e-05 -3e-06 -0 2e-05</velocity>
          <acceleration>-0 0 -0 -0 -0 -0</acceleration>
          <wrench>-0 0 -0 0 -0 0</wrench>
        </link>
      </model>
      <light name='sun'>
        <pose frame=''>0 0 10 0 -0 0</pose>
      </light>
    </state>
    <model name='drc_practice_organge_jersey_barrier'>
      <static>1</static>
      <link name='link'>
        <visual name='visual'>
          <geometry>
            <mesh>
              <uri>model://drc_practice_orange_jersey_barrier/meshes/jersey_barrier.dae</uri>
            </mesh>
          </geometry>
        </visual>
        <collision name='collision'>
          <geometry>
            <mesh>
              <uri>model://drc_practice_orange_jersey_barrier/meshes/jersey_barrier.dae</uri>
            </mesh>
          </geometry>
          <max_contacts>10</max_contacts>
          <surface>
            <contact>
              <ode/>
            </contact>
            <bounce/>
            <friction>
              <torsional>
                <ode/>
              </torsional>
              <ode/>
            </friction>
          </surface>
        </collision>
        <self_collide>0</self_collide>
        <enable_wind>0</enable_wind>
        <kinematic>0</kinematic>
      </link>
      <pose frame=''>3.9268 1.41958 0 0 -0 0</pose>
    </model>
    <model name='frc2016_moat'>
      <static>1</static>
      <link name='link'>
        <inertial>
          <mass>10</mass>
          <pose frame=''>0 0 0.06738 0 -0 0</pose>
          <inertia>
            <ixx>0.312195</ixx>
            <ixy>0</ixy>
            <ixz>0</ixz>
            <iyy>1.35927</iyy>
            <iyz>0</iyz>
            <izz>1.64109</izz>
          </inertia>
        </inertial>
        <visual name='platform'>
          <pose frame=''>0 0 0.0381 0 -0 0</pose>
          <geometry>
            <box>
              <size>1.27 0.5969 0.0762</size>
            </box>
          </geometry>
        </visual>
        <collision name='platform'>
          <pose frame=''>0 0 0.0381 0 -0 0</pose>
          <geometry>
            <box>
              <size>1.27 0.5969 0.0762</size>
            </box>
          </geometry>
          <max_contacts>10</max_contacts>
          <surface>
            <contact>
              <ode/>
            </contact>
            <bounce/>
            <friction>
              <torsional>
                <ode/>
              </torsional>
              <ode/>
            </friction>
          </surface>
        </collision>
        <visual name='tube1_side1'>
          <pose frame=''>0 -0.25876 0.10301 0 -0 0</pose>
          <geometry>
            <box>
              <size>1.27 0.003175 0.0635</size>
            </box>
          </geometry>
          <material>
            <ambient>0.46 0.46 0.46 1</ambient>
            <diffuse>0.46 0.46 0.46 1</diffuse>
          </material>
        </visual>
        <collision name='tube1_side1'>
          <pose frame=''>0 -0.25876 0.10301 0 -0 0</pose>
          <geometry>
            <box>
              <size>1.27 0.003175 0.0635</size>
            </box>
          </geometry>
          <max_contacts>10</max_contacts>
          <surface>
            <contact>
              <ode/>
            </contact>
            <bounce/>
            <friction>
              <torsional>
                <ode/>
              </torsional>
              <ode/>
            </friction>
          </surface>
        </collision>
        <visual name='tube1_side2'>
          <pose frame=''>0 -0.22384 0.10301 0 -0 0</pose>
          <geometry>
            <box>
              <size>1.27 0.003175 0.0635</size>
            </box>
          </geometry>
          <material>
            <ambient>0.46 0.46 0.46 1</ambient>
            <diffuse>0.46 0.46 0.46 1</diffuse>
          </material>
        </visual>
        <collision name='tube1_side2'>
          <pose frame=''>0 -0.22384 0.10301 0 -0 0</pose>
          <geometry>
            <box>
              <size>1.27 0.003175 0.0635</size>
            </box>
          </geometry>
          <max_contacts>10</max_contacts>
          <surface>
            <contact>
              <ode/>
            </contact>
            <bounce/>
            <friction>
              <torsional>
                <ode/>
              </torsional>
              <ode/>
            </friction>
          </surface>
        </collision>
        <visual name='tube1_top'>
          <pose frame=''>0 -0.2413 0.13317 0 -0 0</pose>
          <geometry>
            <box>
              <size>1.27 0.0381 0.003175</size>
            </box>
          </geometry>
          <material>
            <ambient>0.46 0.46 0.46 1</ambient>
            <diffuse>0.46 0.46 0.46 1</diffuse>
          </material>
        </visual>
        <collision name='tube1_top'>
          <pose frame=''>0 -0.2413 0.13317 0 -0 0</pose>
          <geometry>
            <box>
              <size>1.27 0.0381 0.003175</size>
            </box>
          </geometry>
          <max_contacts>10</max_contacts>
          <surface>
            <contact>
              <ode/>
            </contact>
            <bounce/>
            <friction>
              <torsional>
                <ode/>
              </torsional>
              <ode/>
            </friction>
          </surface>
        </collision>
        <visual name='tube2_side1'>
          <pose frame=''>0 0.22384 0.10301 0 -0 0</pose>
          <geometry>
            <box>
              <size>1.27 0.003175 0.0635</size>
            </box>
          </geometry>
          <material>
            <ambient>0.46 0.46 0.46 1</ambient>
            <diffuse>0.46 0.46 0.46 1</diffuse>
          </material>
        </visual>
        <collision name='tube2_side1'>
          <pose frame=''>0 0.22384 0.10301 0 -0 0</pose>
          <geometry>
            <box>
              <size>1.27 0.003175 0.0635</size>
            </box>
          </geometry>
          <max_contacts>10</max_contacts>
          <surface>
            <contact>
              <ode/>
            </contact>
            <bounce/>
            <friction>
              <torsional>
                <ode/>
              </torsional>
              <ode/>
            </friction>
          </surface>
        </collision>
        <visual name='tube2_side2'>
          <pose frame=''>0 0.25876 0.10301 0 -0 0</pose>
          <geometry>
            <box>
              <size>1.27 0.003175 0.0635</size>
            </box>
          </geometry>
          <material>
            <ambient>0.46 0.46 0.46 1</ambient>
            <diffuse>0.46 0.46 0.46 1</diffuse>
          </material>
        </visual>
        <collision name='tube2_side2'>
          <pose frame=''>0 0.25876 0.10301 0 -0 0</pose>
          <geometry>
            <box>
              <size>1.27 0.003175 0.0635</size>
            </box>
          </geometry>
          <max_contacts>10</max_contacts>
          <surface>
            <contact>
              <ode/>
            </contact>
            <bounce/>
            <friction>
              <torsional>
                <ode/>
              </torsional>
              <ode/>
            </friction>
          </surface>
        </collision>
        <visual name='tube2_top'>
          <pose frame=''>0 0.2413 0.13317 0 -0 0</pose>
          <geometry>
            <box>
              <size>1.27 0.0381 0.003175</size>
            </box>
          </geometry>
          <material>
            <ambient>0.46 0.46 0.46 1</ambient>
            <diffuse>0.46 0.46 0.46 1</diffuse>
          </material>
        </visual>
        <collision name='tube2_top'>
          <pose frame=''>0 0.2413 0.13317 0 -0 0</pose>
          <geometry>
            <box>
              <size>1.27 0.0381 0.003175</size>
            </box>
          </geometry>
          <max_contacts>10</max_contacts>
          <surface>
            <contact>
              <ode/>
            </contact>
            <bounce/>
            <friction>
              <torsional>
                <ode/>
              </torsional>
              <ode/>
            </friction>
          </surface>
        </collision>
        <self_collide>0</self_collide>
        <enable_wind>0</enable_wind>
        <kinematic>0</kinematic>
      </link>
      <pose frame=''>8.06891 -1.33573 0 0 -0 0</pose>
    </model>
    <model name='frc2016_portcullis'>
      <link name='base'>
        <inertial>
          <mass>50</mass>
          <pose frame=''>0 0 1.02941 0 -0 0</pose>
          <inertia>
            <ixx>3.81711</ixx>
            <ixy>0</ixy>
            <ixz>0</ixz>
            <iyy>4.87698</iyy>
            <iyz>0</iyz>
            <izz>1.6283</izz>
          </inertia>
        </inertial>
        <visual name='platform'>
          <pose frame=''>0 0 0.07284 0 -0 0</pose>
          <geometry>
            <box>
              <size>1.27 0.5842 0.003175</size>
            </box>
          </geometry>
        </visual>
        <collision name='platform'>
          <pose frame=''>0 0 0.07284 0 -0 0</pose>
          <geometry>
            <box>
              <size>1.27 0.5842 0.003175</size>
            </box>
          </geometry>
          <max_contacts>10</max_contacts>
          <surface>
            <contact>
              <ode/>
            </contact>
            <bounce/>
            <friction>
              <torsional>
                <ode/>
              </torsional>
              <ode/>
            </friction>
          </surface>
        </collision>
        <visual name='left_column'>
          <pose frame=''>0.59284 0 0.99042 0 -0 0</pose>
          <geometry>
            <box>
              <size>0.08375 0.28575 1.83198</size>
            </box>
          </geometry>
        </visual>
        <collision name='left_column'>
          <pose frame=''>0.59284 0 0.99042 0 -0 0</pose>
          <geometry>
            <box>
              <size>0.08375 0.28575 1.83198</size>
            </box>
          </geometry>
          <max_contacts>10</max_contacts>
          <surface>
            <contact>
              <ode/>
            </contact>
            <bounce/>
            <friction>
              <torsional>
                <ode/>
              </torsional>
              <ode/>
            </friction>
          </surface>
        </collision>
        <visual name='right_column'>
          <pose frame=''>-0.57759 0 0.99042 0 -0 0</pose>
          <geometry>
            <box>
              <size>0.08375 0.28575 1.83198</size>
            </box>
          </geometry>
        </visual>
        <collision name='right_column'>
          <pose frame=''>-0.57759 0 0.99042 0 -0 0</pose>
          <geometry>
            <box>
              <size>0.08375 0.28575 1.83198</size>
            </box>
          </geometry>
          <max_contacts>10</max_contacts>
          <surface>
            <contact>
              <ode/>
            </contact>
            <bounce/>
            <friction>
              <torsional>
                <ode/>
              </torsional>
              <ode/>
            </friction>
          </surface>
        </collision>
        <visual name='top'>
          <pose frame=''>-0.00034 0 1.77722 0 -0 0</pose>
          <geometry>
            <box>
              <size>1.22962 0.28575 0.26657</size>
            </box>
          </geometry>
        </visual>
        <collision name='top'>
          <pose frame=''>-0.00034 0 1.77722 0 -0 0</pose>
          <geometry>
            <box>
              <size>1.22962 0.28575 0.26657</size>
            </box>
          </geometry>
          <max_contacts>10</max_contacts>
          <surface>
            <contact>
              <ode/>
            </contact>
            <bounce/>
            <friction>
              <torsional>
                <ode/>
              </torsional>
              <ode/>
            </friction>
          </surface>
        </collision>
        <visual name='castor1'>
          <pose frame=''>-0.45651 -0.16234 0.03272 0 -0 0</pose>
          <geometry>
            <sphere>
              <radius>0.03272</radius>
            </sphere>
          </geometry>
        </visual>
        <collision name='castor1'>
          <pose frame=''>-0.45651 -0.16234 0.03272 0 -0 0</pose>
          <geometry>
            <sphere>
              <radius>0.03272</radius>
            </sphere>
          </geometry>
          <max_contacts>10</max_contacts>
          <surface>
            <contact>
              <ode/>
            </contact>
            <bounce/>
            <friction>
              <torsional>
                <ode/>
              </torsional>
              <ode/>
            </friction>
          </surface>
        </collision>
        <visual name='castor2'>
          <pose frame=''>-0.27883 0.21836 0.03272 0 -0 0</pose>
          <geometry>
            <sphere>
              <radius>0.03272</radius>
            </sphere>
          </geometry>
        </visual>
        <collision name='castor2'>
          <pose frame=''>-0.27883 0.21836 0.03272 0 -0 0</pose>
          <geometry>
            <sphere>
              <radius>0.03272</radius>
            </sphere>
          </geometry>
          <max_contacts>10</max_contacts>
          <surface>
            <contact>
              <ode/>
            </contact>
            <bounce/>
            <friction>
              <torsional>
                <ode/>
              </torsional>
              <ode/>
            </friction>
          </surface>
        </collision>
        <visual name='castor3'>
          <pose frame=''>0.28083 0.21906 0.03272 0 -0 0</pose>
          <geometry>
            <sphere>
              <radius>0.03272</radius>
            </sphere>
          </geometry>
        </visual>
        <collision name='castor3'>
          <pose frame=''>0.28083 0.21906 0.03272 0 -0 0</pose>
          <geometry>
            <sphere>
              <radius>0.03272</radius>
            </sphere>
          </geometry>
          <max_contacts>10</max_contacts>
          <surface>
            <contact>
              <ode/>
            </contact>
            <bounce/>
            <friction>
              <torsional>
                <ode/>
              </torsional>
              <ode/>
            </friction>
          </surface>
        </collision>
        <visual name='castor4'>
          <pose frame=''>0.45871 -0.16186 0.03272 0 -0 0</pose>
          <geometry>
            <sphere>
              <radius>0.03272</radius>
            </sphere>
          </geometry>
        </visual>
        <collision name='castor4'>
          <pose frame=''>0.45871 -0.16186 0.03272 0 -0 0</pose>
          <geometry>
            <sphere>
              <radius>0.03272</radius>
            </sphere>
          </geometry>
          <max_contacts>10</max_contacts>
          <surface>
            <contact>
              <ode/>
            </contact>
            <bounce/>
            <friction>
              <torsional>
                <ode/>
              </torsional>
              <ode/>
            </friction>
          </surface>
        </collision>
        <self_collide>0</self_collide>
        <enable_wind>0</enable_wind>
        <kinematic>0</kinematic>
      </link>
      <link name='gate'>
        <pose frame=''>-0.0287 0.02885 0.93327 0 -0 0</pose>
        <inertial>
          <mass>2</mass>
          <pose frame=''>0 0 0 0 -0 0</pose>
          <inertia>
            <ixx>3.81711</ixx>
            <ixy>0</ixy>
            <ixz>0</ixz>
            <iyy>4.87698</iyy>
            <iyz>0</iyz>
            <izz>1.6283</izz>
          </inertia>
        </inertial>
        <collision name='collision'>
          <geometry>
            <box>
              <size>1.1938 0.02496 1.45732</size>
            </box>
          </geometry>
          <max_contacts>10</max_contacts>
          <surface>
            <contact>
              <ode/>
            </contact>
            <bounce/>
            <friction>
              <torsional>
                <ode/>
              </torsional>
              <ode/>
            </friction>
          </surface>
        </collision>
        <visual name='horz_1'>
          <pose frame=''>0 0 -0.70326 0 -0 0</pose>
          <geometry>
            <box>
              <size>1.1938 0.02496 0.0508</size>
            </box>
          </geometry>
          <material>
            <ambient>0.4 0.4 0.4 1</ambient>
            <diffuse>0.4 0.4 0.4 1</diffuse>
          </material>
        </visual>
        <visual name='horz_2'>
          <pose frame=''>0 0 -0.44926 0 -0 0</pose>
          <geometry>
            <box>
              <size>1.1938 0.02496 0.0508</size>
            </box>
          </geometry>
          <material>
            <ambient>0.4 0.4 0.4 1</ambient>
            <diffuse>0.4 0.4 0.4 1</diffuse>
          </material>
        </visual>
        <visual name='horz_3'>
          <pose frame=''>0 0 -0.14517 0 -0 0</pose>
          <geometry>
            <box>
              <size>1.1938 0.02496 0.0508</size>
            </box>
          </geometry>
          <material>
            <ambient>0.4 0.4 0.4 1</ambient>
            <diffuse>0.4 0.4 0.4 1</diffuse>
          </material>
        </visual>
        <visual name='horz_4'>
          <pose frame=''>0 0 0.16034 0 -0 0</pose>
          <geometry>
            <box>
              <size>1.1938 0.02496 0.0508</size>
            </box>
          </geometry>
          <material>
            <ambient>0.4 0.4 0.4 1</ambient>
            <diffuse>0.4 0.4 0.4 1</diffuse>
          </material>
        </visual>
        <visual name='horz_5'>
          <pose frame=''>0 0 0.46514 0 -0 0</pose>
          <geometry>
            <box>
              <size>1.1938 0.02496 0.0508</size>
            </box>
          </geometry>
          <material>
            <ambient>0.4 0.4 0.4 1</ambient>
            <diffuse>0.4 0.4 0.4 1</diffuse>
          </material>
        </visual>
        <visual name='horz_6'>
          <pose frame=''>0 0 0.72994 0 -0 0</pose>
          <geometry>
            <box>
              <size>1.1938 0.02496 0.0508</size>
            </box>
          </geometry>
          <material>
            <ambient>0.4 0.4 0.4 1</ambient>
            <diffuse>0.4 0.4 0.4 1</diffuse>
          </material>
        </visual>
        <visual name='vert_1'>
          <pose frame=''>-0.58448 0 0 0 -0 0</pose>
          <geometry>
            <box>
              <size>0.02495 0.02496 1.45732</size>
            </box>
          </geometry>
          <material>
            <ambient>0.4 0.4 0.4 1</ambient>
            <diffuse>0.4 0.4 0.4 1</diffuse>
          </material>
        </visual>
        <visual name='vert_2'>
          <pose frame=''>-0.38128 0 0 0 -0 0</pose>
          <geometry>
            <box>
              <size>0.0508 0.02496 1.45732</size>
            </box>
          </geometry>
          <material>
            <ambient>0.4 0.4 0.4 1</ambient>
            <diffuse>0.4 0.4 0.4 1</diffuse>
          </material>
        </visual>
        <visual name='vert_3'>
          <pose frame=''>-0.12728 0 0 0 -0 0</pose>
          <geometry>
            <box>
              <size>0.0508 0.02496 1.45732</size>
            </box>
          </geometry>
          <material>
            <ambient>0.4 0.4 0.4 1</ambient>
            <diffuse>0.4 0.4 0.4 1</diffuse>
          </material>
        </visual>
        <visual name='vert_4'>
          <pose frame=''>0.12672 0 0 0 -0 0</pose>
          <geometry>
            <box>
              <size>0.0508 0.02496 1.45732</size>
            </box>
          </geometry>
          <material>
            <ambient>0.4 0.4 0.4 1</ambient>
            <diffuse>0.4 0.4 0.4 1</diffuse>
          </material>
        </visual>
        <visual name='vert_5'>
          <pose frame=''>0.38072 0 0 0 -0 0</pose>
          <geometry>
            <box>
              <size>0.0508 0.02496 1.45732</size>
            </box>
          </geometry>
          <material>
            <ambient>0.4 0.4 0.4 1</ambient>
            <diffuse>0.4 0.4 0.4 1</diffuse>
          </material>
        </visual>
        <visual name='vert_6'>
          <pose frame=''>0.58392 0 0 0 -0 0</pose>
          <geometry>
            <box>
              <size>0.02495 0.02496 1.45732</size>
            </box>
          </geometry>
          <material>
            <ambient>0.4 0.4 0.4 1</ambient>
            <diffuse>0.4 0.4 0.4 1</diffuse>
          </material>
        </visual>
        <self_collide>0</self_collide>
        <enable_wind>0</enable_wind>
        <kinematic>0</kinematic>
      </link>
      <joint name='joint' type='prismatic'>
        <parent>base</parent>
        <child>gate</child>
        <axis>
          <xyz>0 0 1</xyz>
          <limit>
            <lower>0</lower>
            <upper>1</upper>
          </limit>
          <use_parent_model_frame>0</use_parent_model_frame>
          <dynamics>
            <spring_reference>0</spring_reference>
            <spring_stiffness>0</spring_stiffness>
          </dynamics>
        </axis>
      </joint>
      <pose frame=''>2.35698 -4.66017 0 0 -0 0</pose>
    </model>
    <model name='polaris_ranger_ev'>
      <link name='chassis'>
        <inertial>
          <mass>720</mass>
          <inertia>
            <ixx>140</ixx>
            <ixy>0</ixy>
            <iyy>550</iyy>
            <ixz>0</ixz>
            <iyz>0</iyz>
            <izz>550</izz>
          </inertia>
          <pose frame=''>0.1 0 0.4 0 -0 0</pose>
        </inertial>
        <visual name='visual'>
          <pose frame=''>0 0 0 0 0 -1.5708</pose>
          <geometry>
            <mesh>
              <uri>model://polaris_ranger_ev/meshes/polaris.dae</uri>
              <submesh>
                <name>Ranger</name>
                <center>0</center>
              </submesh>
            </mesh>
          </geometry>
          <material>
            <script>
              <uri>model://polaris_ranger_ev/materials/scripts</uri>
              <uri>model://polaris_ranger_ev/materials/textures</uri>
              <name>Polaris/Diffuse</name>
            </script>
          </material>
        </visual>
        <collision name='chassis_bottom'>
          <pose frame=''>0.1 0 0.37 0 -0 0</pose>
          <geometry>
            <box>
              <size>1.5 1.34 0.06</size>
            </box>
          </geometry>
          <max_contacts>10</max_contacts>
          <surface>
            <contact>
              <ode/>
            </contact>
            <bounce/>
            <friction>
              <torsional>
                <ode/>
              </torsional>
              <ode/>
            </friction>
          </surface>
        </collision>
        <collision name='cargo_bottom'>
          <pose frame=''>-0.9 0 0.9 0 -0 0</pose>
          <geometry>
            <box>
              <size>0.9 1.2 0.01</size>
            </box>
          </geometry>
          <max_contacts>10</max_contacts>
          <surface>
            <contact>
              <ode/>
            </contact>
            <bounce/>
            <friction>
              <torsional>
                <ode/>
              </torsional>
              <ode/>
            </friction>
          </surface>
        </collision>
        <collision name='cargo_front'>
          <pose frame=''>-0.45 0 1.025 0 -0 0</pose>
          <geometry>
            <box>
              <size>0.05 1.2 0.25</size>
            </box>
          </geometry>
          <max_contacts>10</max_contacts>
          <surface>
            <contact>
              <ode/>
            </contact>
            <bounce/>
            <friction>
              <torsional>
                <ode/>
              </torsional>
              <ode/>
            </friction>
          </surface>
        </collision>
        <collision name='cargo_back'>
          <pose frame=''>-1.35 0 1.025 0 -0 0</pose>
          <geometry>
            <box>
              <size>0.05 1.2 0.25</size>
            </box>
          </geometry>
          <max_contacts>10</max_contacts>
          <surface>
            <contact>
              <ode/>
            </contact>
            <bounce/>
            <friction>
              <torsional>
                <ode/>
              </torsional>
              <ode/>
            </friction>
          </surface>
        </collision>
        <collision name='cargo_left'>
          <pose frame=''>-0.9 0.6 1.025 0 -0 0</pose>
          <geometry>
            <box>
              <size>0.9 0.05 0.25</size>
            </box>
          </geometry>
          <max_contacts>10</max_contacts>
          <surface>
            <contact>
              <ode/>
            </contact>
            <bounce/>
            <friction>
              <torsional>
                <ode/>
              </torsional>
              <ode/>
            </friction>
          </surface>
        </collision>
        <collision name='cargo_right'>
          <pose frame=''>-0.9 -0.6 1.025 0 -0 0</pose>
          <geometry>
            <box>
              <size>0.9 0.05 0.25</size>
            </box>
          </geometry>
          <max_contacts>10</max_contacts>
          <surface>
            <contact>
              <ode/>
            </contact>
            <bounce/>
            <friction>
              <torsional>
                <ode/>
              </torsional>
              <ode/>
            </friction>
          </surface>
        </collision>
        <collision name='seat'>
          <pose frame=''>-0.1 0 0.56 0 -0 0</pose>
          <geometry>
            <box>
              <size>0.6 1.22 0.5</size>
            </box>
          </geometry>
          <surface>
            <contact>
              <ode>
                <min_depth>0.01</min_depth>
              </ode>
            </contact>
            <bounce/>
            <friction>
              <torsional>
                <ode/>
              </torsional>
              <ode/>
            </friction>
          </surface>
          <max_contacts>10</max_contacts>
        </collision>
        <collision name='mud_seat'>
          <pose frame=''>-0.1 0 0.81 0 -0 0</pose>
          <geometry>
            <box>
              <size>0.6 1.15 0.1</size>
            </box>
          </geometry>
          <surface>
            <contact>
              <collide_without_contact>1</collide_without_contact>
              <ode/>
            </contact>
            <bounce/>
            <friction>
              <torsional>
                <ode/>
              </torsional>
              <ode/>
            </friction>
          </surface>
          <max_contacts>10</max_contacts>
        </collision>
        <sensor name='seat_contact' type='contact'>
          <always_on>1</always_on>
          <update_rate>1000</update_rate>
          <contact>
            <collision>mud_seat</collision>
            <topic>__default_topic__</topic>
          </contact>
        </sensor>
        <collision name='seat_back'>
          <pose frame=''>-0.3 0 1.125 0 -0.2 0</pose>
          <geometry>
            <box>
              <size>0.06 1 0.4</size>
            </box>
          </geometry>
          <max_contacts>10</max_contacts>
          <surface>
            <contact>
              <ode/>
            </contact>
            <bounce/>
            <friction>
              <torsional>
                <ode/>
              </torsional>
              <ode/>
            </friction>
          </surface>
        </collision>
        <collision name='engine'>
          <pose frame=''>1.05 0 0.7 0 -0 0</pose>
          <geometry>
            <box>
              <size>0.58 1 0.8</size>
            </box>
          </geometry>
          <max_contacts>10</max_contacts>
          <surface>
            <contact>
              <ode/>
            </contact>
            <bounce/>
            <friction>
              <torsional>
                <ode/>
              </torsional>
              <ode/>
            </friction>
          </surface>
        </collision>
        <collision name='handle_left_middle'>
          <pose frame=''>-0.3 0.61 1.055 0 -0.2 0</pose>
          <geometry>
            <cylinder>
              <radius>0.02</radius>
              <length>0.17</length>
            </cylinder>
          </geometry>
          <max_contacts>10</max_contacts>
          <surface>
            <contact>
              <ode/>
            </contact>
            <bounce/>
            <friction>
              <torsional>
                <ode/>
              </torsional>
              <ode/>
            </friction>
          </surface>
        </collision>
        <collision name='handle_right_middle'>
          <pose frame=''>-0.3 -0.61 1.055 0 -0.2 0</pose>
          <geometry>
            <cylinder>
              <radius>0.02</radius>
              <length>0.17</length>
            </cylinder>
          </geometry>
          <max_contacts>10</max_contacts>
          <surface>
            <contact>
              <ode/>
            </contact>
            <bounce/>
            <friction>
              <torsional>
                <ode/>
              </torsional>
              <ode/>
            </friction>
          </surface>
        </collision>
        <collision name='rollcage_top_left'>
          <pose frame=''>0 0.61 1.92 3.14159 1.53159 3.14159</pose>
          <geometry>
            <cylinder>
              <radius>0.03</radius>
              <length>0.68</length>
            </cylinder>
          </geometry>
          <max_contacts>10</max_contacts>
          <surface>
            <contact>
              <ode/>
            </contact>
            <bounce/>
            <friction>
              <torsional>
                <ode/>
              </torsional>
              <ode/>
            </friction>
          </surface>
        </collision>
        <collision name='rollcage_top_right'>
          <pose frame=''>0 -0.61 1.92 3.14159 1.53159 3.14159</pose>
          <geometry>
            <cylinder>
              <radius>0.03</radius>
              <length>0.68</length>
            </cylinder>
          </geometry>
          <max_contacts>10</max_contacts>
          <surface>
            <contact>
              <ode/>
            </contact>
            <bounce/>
            <friction>
              <torsional>
                <ode/>
              </torsional>
              <ode/>
            </friction>
          </surface>
        </collision>
        <collision name='rollcage_top_front'>
          <pose frame=''>0.325 0 1.89 1.5708 -0 0</pose>
          <geometry>
            <cylinder>
              <radius>0.03</radius>
              <length>1.22</length>
            </cylinder>
          </geometry>
          <max_contacts>10</max_contacts>
          <surface>
            <contact>
              <ode/>
            </contact>
            <bounce/>
            <friction>
              <torsional>
                <ode/>
              </torsional>
              <ode/>
            </friction>
          </surface>
        </collision>
        <collision name='rollcage_top_back'>
          <pose frame=''>-0.33 0 1.92 1.5708 -0 0</pose>
          <geometry>
            <cylinder>
              <radius>0.03</radius>
              <length>1.22</length>
            </cylinder>
          </geometry>
          <max_contacts>10</max_contacts>
          <surface>
            <contact>
              <ode/>
            </contact>
            <bounce/>
            <friction>
              <torsional>
                <ode/>
              </torsional>
              <ode/>
            </friction>
          </surface>
        </collision>
        <collision name='rollcage_front_left'>
          <pose frame=''>0.54 0.61 1.45 0 -0.44 0</pose>
          <geometry>
            <cylinder>
              <radius>0.03</radius>
              <length>1.04</length>
            </cylinder>
          </geometry>
          <max_contacts>10</max_contacts>
          <surface>
            <contact>
              <ode/>
            </contact>
            <bounce/>
            <friction>
              <torsional>
                <ode/>
              </torsional>
              <ode/>
            </friction>
          </surface>
        </collision>
        <collision name='rollcage_front_right'>
          <pose frame=''>0.54 -0.61 1.45 0 -0.44 0</pose>
          <geometry>
            <cylinder>
              <radius>0.03</radius>
              <length>1.04</length>
            </cylinder>
          </geometry>
          <max_contacts>10</max_contacts>
          <surface>
            <contact>
              <ode/>
            </contact>
            <bounce/>
            <friction>
              <torsional>
                <ode/>
              </torsional>
              <ode/>
            </friction>
          </surface>
        </collision>
        <collision name='fender_front_right'>
          <pose frame=''>0.64 -0.61 0.7 0 0.35 0</pose>
          <geometry>
            <cylinder>
              <radius>0.03</radius>
              <length>0.72</length>
            </cylinder>
          </geometry>
          <max_contacts>10</max_contacts>
          <surface>
            <contact>
              <ode/>
            </contact>
            <bounce/>
            <friction>
              <torsional>
                <ode/>
              </torsional>
              <ode/>
            </friction>
          </surface>
        </collision>
        <collision name='fender_front_left'>
          <pose frame=''>0.64 0.61 0.7 0 0.35 0</pose>
          <geometry>
            <cylinder>
              <radius>0.03</radius>
              <length>0.72</length>
            </cylinder>
          </geometry>
          <max_contacts>10</max_contacts>
          <surface>
            <contact>
              <ode/>
            </contact>
            <bounce/>
            <friction>
              <torsional>
                <ode/>
              </torsional>
              <ode/>
            </friction>
          </surface>
        </collision>
        <collision name='rollcage_back_left'>
          <pose frame=''>-0.37 0.61 1.25 0 -0.14 0</pose>
          <geometry>
            <cylinder>
              <radius>0.03</radius>
              <length>0.9</length>
            </cylinder>
          </geometry>
          <max_contacts>10</max_contacts>
          <surface>
            <contact>
              <ode/>
            </contact>
            <bounce/>
            <friction>
              <torsional>
                <ode/>
              </torsional>
              <ode/>
            </friction>
          </surface>
        </collision>
        <collision name='rollcage_back_right'>
          <pose frame=''>-0.37 -0.61 1.25 0 -0.14 0</pose>
          <geometry>
            <cylinder>
              <radius>0.03</radius>
              <length>0.9</length>
            </cylinder>
          </geometry>
          <max_contacts>10</max_contacts>
          <surface>
            <contact>
              <ode/>
            </contact>
            <bounce/>
            <friction>
              <torsional>
                <ode/>
              </torsional>
              <ode/>
            </friction>
          </surface>
        </collision>
        <collision name='rollcage_back_midleft'>
          <pose frame=''>-0.37 0.155 1.25 0 -0.14 0</pose>
          <geometry>
            <cylinder>
              <radius>0.023</radius>
              <length>0.9</length>
            </cylinder>
          </geometry>
          <max_contacts>10</max_contacts>
          <surface>
            <contact>
              <ode/>
            </contact>
            <bounce/>
            <friction>
              <torsional>
                <ode/>
              </torsional>
              <ode/>
            </friction>
          </surface>
        </collision>
        <collision name='rollcage_back_midright'>
          <pose frame=''>-0.37 -0.155 1.25 0 -0.14 0</pose>
          <geometry>
            <cylinder>
              <radius>0.023</radius>
              <length>0.9</length>
            </cylinder>
          </geometry>
          <max_contacts>10</max_contacts>
          <surface>
            <contact>
              <ode/>
            </contact>
            <bounce/>
            <friction>
              <torsional>
                <ode/>
              </torsional>
              <ode/>
            </friction>
          </surface>
        </collision>
        <collision name='rollcage_back_upper_left'>
          <pose frame=''>-0.38 0.61 1.82 0 0.4 0</pose>
          <geometry>
            <cylinder>
              <radius>0.03</radius>
              <length>0.29</length>
            </cylinder>
          </geometry>
          <max_contacts>10</max_contacts>
          <surface>
            <contact>
              <ode/>
            </contact>
            <bounce/>
            <friction>
              <torsional>
                <ode/>
              </torsional>
              <ode/>
            </friction>
          </surface>
        </collision>
        <collision name='rollcage_back_upper_right'>
          <pose frame=''>-0.38 -0.61 1.82 0 0.4 0</pose>
          <geometry>
            <cylinder>
              <radius>0.03</radius>
              <length>0.29</length>
            </cylinder>
          </geometry>
          <max_contacts>10</max_contacts>
          <surface>
            <contact>
              <ode/>
            </contact>
            <bounce/>
            <friction>
              <torsional>
                <ode/>
              </torsional>
              <ode/>
            </friction>
          </surface>
        </collision>
        <collision name='rollcage_back_upper_midleft'>
          <pose frame=''>-0.38 0.155 1.82 0 0.4 0</pose>
          <geometry>
            <cylinder>
              <radius>0.023</radius>
              <length>0.29</length>
            </cylinder>
          </geometry>
          <max_contacts>10</max_contacts>
          <surface>
            <contact>
              <ode/>
            </contact>
            <bounce/>
            <friction>
              <torsional>
                <ode/>
              </torsional>
              <ode/>
            </friction>
          </surface>
        </collision>
        <collision name='rollcage_back_upper_midright'>
          <pose frame=''>-0.38 -0.155 1.82 0 0.4 0</pose>
          <geometry>
            <cylinder>
              <radius>0.023</radius>
              <length>0.29</length>
            </cylinder>
          </geometry>
          <max_contacts>10</max_contacts>
          <surface>
            <contact>
              <ode/>
            </contact>
            <bounce/>
            <friction>
              <torsional>
                <ode/>
              </torsional>
              <ode/>
            </friction>
          </surface>
        </collision>
        <self_collide>0</self_collide>
        <enable_wind>0</enable_wind>
        <kinematic>0</kinematic>
      </link>
      <link name='rear_right_wheel'>
        <pose frame=''>-0.85 -0.6 0.32 1.52 -0 0</pose>
        <inertial>
          <mass>12</mass>
          <inertia>
            <ixx>0.5</ixx>
            <ixy>0</ixy>
            <iyy>0.5</iyy>
            <ixz>0</ixz>
            <iyz>0</iyz>
            <izz>1</izz>
          </inertia>
          <pose frame=''>0 0 0 0 -0 0</pose>
        </inertial>
        <collision name='collision'>
          <geometry>
            <cylinder>
              <radius>0.32</radius>
              <length>0.23</length>
            </cylinder>
          </geometry>
          <max_contacts>1</max_contacts>
          <surface>
            <friction>
              <ode>
                <mu>1</mu>
                <mu2>1</mu2>
                <fdir1>0 0 1</fdir1>
                <slip1>0</slip1>
                <slip2>0</slip2>
              </ode>
              <torsional>
                <ode/>
              </torsional>
            </friction>
            <contact>
              <ode>
                <min_depth>0.005</min_depth>
                <kp>1e+08</kp>
              </ode>
            </contact>
            <bounce/>
          </surface>
        </collision>
        <visual name='visual'>
          <pose frame=''>0 0 0 3.14159 -1.57079 3.14159</pose>
          <geometry>
            <mesh>
              <uri>model://polaris_ranger_ev/meshes/polaris.dae</uri>
              <submesh>
                <name>Rear_Wheel_Right</name>
                <center>1</center>
              </submesh>
            </mesh>
          </geometry>
          <material>
            <script>
              <uri>model://polaris_ranger_ev/materials/scripts</uri>
              <uri>model://polaris_ranger_ev/materials/textures</uri>
              <name>Polaris/Diffuse</name>
            </script>
          </material>
        </visual>
        <self_collide>0</self_collide>
        <enable_wind>0</enable_wind>
        <kinematic>0</kinematic>
      </link>
      <link name='rear_left_wheel'>
        <pose frame=''>-0.85 0.6 0.32 -1.52 0 0</pose>
        <inertial>
          <mass>12</mass>
          <inertia>
            <ixx>0.5</ixx>
            <ixy>0</ixy>
            <iyy>0.5</iyy>
            <ixz>0</ixz>
            <iyz>0</iyz>
            <izz>1</izz>
          </inertia>
          <pose frame=''>0 0 0 0 -0 0</pose>
        </inertial>
        <collision name='collision'>
          <geometry>
            <cylinder>
              <radius>0.32</radius>
              <length>0.23</length>
            </cylinder>
          </geometry>
          <max_contacts>1</max_contacts>
          <surface>
            <friction>
              <ode>
                <mu>1</mu>
                <mu2>1</mu2>
                <fdir1>0 0 1</fdir1>
                <slip1>0</slip1>
                <slip2>0</slip2>
              </ode>
              <torsional>
                <ode/>
              </torsional>
            </friction>
            <contact>
              <ode>
                <min_depth>0.005</min_depth>
                <kp>1e+08</kp>
              </ode>
            </contact>
            <bounce/>
          </surface>
        </collision>
        <visual name='visual'>
          <pose frame=''>0 0 0 3.14159 -1.57079 3.14159</pose>
          <geometry>
            <mesh>
              <uri>model://polaris_ranger_ev/meshes/polaris.dae</uri>
              <submesh>
                <name>Rear_Wheel_Left</name>
                <center>1</center>
              </submesh>
            </mesh>
          </geometry>
          <material>
            <script>
              <uri>model://polaris_ranger_ev/materials/scripts</uri>
              <uri>model://polaris_ranger_ev/materials/textures</uri>
              <name>Polaris/Diffuse</name>
            </script>
          </material>
        </visual>
        <self_collide>0</self_collide>
        <enable_wind>0</enable_wind>
        <kinematic>0</kinematic>
      </link>
      <link name='front_right_wheel'>
        <pose frame=''>1.03 -0.6 0.32 1.52 -0 0</pose>
        <inertial>
          <mass>12</mass>
          <inertia>
            <ixx>0.5</ixx>
            <ixy>0</ixy>
            <iyy>0.5</iyy>
            <ixz>0</ixz>
            <iyz>0</iyz>
            <izz>1</izz>
          </inertia>
          <pose frame=''>0 0 0 0 -0 0</pose>
        </inertial>
        <collision name='collision'>
          <geometry>
            <cylinder>
              <radius>0.32</radius>
              <length>0.23</length>
            </cylinder>
          </geometry>
          <max_contacts>1</max_contacts>
          <surface>
            <friction>
              <ode>
                <mu>1</mu>
                <mu2>1</mu2>
                <fdir1>0 0 1</fdir1>
                <slip1>0</slip1>
                <slip2>0</slip2>
              </ode>
              <torsional>
                <ode/>
              </torsional>
            </friction>
            <contact>
              <ode>
                <min_depth>0.005</min_depth>
                <kp>1e+08</kp>
              </ode>
            </contact>
            <bounce/>
          </surface>
        </collision>
        <visual name='visual'>
          <pose frame=''>0 0 0 3.14159 -1.57079 3.14159</pose>
          <geometry>
            <mesh>
              <uri>model://polaris_ranger_ev/meshes/polaris.dae</uri>
              <submesh>
                <name>Front_Wheel_Right</name>
                <center>1</center>
              </submesh>
            </mesh>
          </geometry>
          <material>
            <script>
              <uri>model://polaris_ranger_ev/materials/scripts</uri>
              <uri>model://polaris_ranger_ev/materials/textures</uri>
              <name>Polaris/Diffuse</name>
            </script>
          </material>
        </visual>
        <self_collide>0</self_collide>
        <enable_wind>0</enable_wind>
        <kinematic>0</kinematic>
      </link>
      <link name='front_right_wheel_steering_block'>
        <pose frame=''>1.03 -0.5 0.32 1.5708 -0 0</pose>
        <inertial>
          <mass>1</mass>
          <inertia>
            <ixx>1</ixx>
            <ixy>0</ixy>
            <iyy>1</iyy>
            <ixz>0</ixz>
            <iyz>0</iyz>
            <izz>1</izz>
          </inertia>
          <pose frame=''>0 0 0 0 -0 0</pose>
        </inertial>
        <collision name='collision'>
          <geometry>
            <cylinder>
              <radius>0.05</radius>
              <length>0.01</length>
            </cylinder>
          </geometry>
          <max_contacts>10</max_contacts>
          <surface>
            <contact>
              <ode/>
            </contact>
            <bounce/>
            <friction>
              <torsional>
                <ode/>
              </torsional>
              <ode/>
            </friction>
          </surface>
        </collision>
        <self_collide>0</self_collide>
        <enable_wind>0</enable_wind>
        <kinematic>0</kinematic>
      </link>
      <link name='front_left_wheel'>
        <pose frame=''>1.03 0.6 0.32 -1.52 0 0</pose>
        <inertial>
          <mass>12</mass>
          <inertia>
            <ixx>0.5</ixx>
            <ixy>0</ixy>
            <iyy>0.5</iyy>
            <ixz>0</ixz>
            <iyz>0</iyz>
            <izz>1</izz>
          </inertia>
          <pose frame=''>0 0 0 0 -0 0</pose>
        </inertial>
        <collision name='collision'>
          <geometry>
            <cylinder>
              <radius>0.32</radius>
              <length>0.23</length>
            </cylinder>
          </geometry>
          <max_contacts>1</max_contacts>
          <surface>
            <friction>
              <ode>
                <mu>1</mu>
                <mu2>1</mu2>
                <fdir1>0 0 1</fdir1>
                <slip1>0</slip1>
                <slip2>0</slip2>
              </ode>
              <torsional>
                <ode/>
              </torsional>
            </friction>
            <contact>
              <ode>
                <min_depth>0.005</min_depth>
                <kp>1e+08</kp>
              </ode>
            </contact>
            <bounce/>
          </surface>
        </collision>
        <visual name='visual'>
          <pose frame=''>0 0 0 -3e-06 1.57079 3.14159</pose>
          <geometry>
            <mesh>
              <uri>model://polaris_ranger_ev/meshes/polaris.dae</uri>
              <submesh>
                <name>Front_Wheel_Left</name>
                <center>1</center>
              </submesh>
            </mesh>
          </geometry>
          <material>
            <script>
              <uri>model://polaris_ranger_ev/materials/scripts</uri>
              <uri>model://polaris_ranger_ev/materials/textures</uri>
              <name>Polaris/Diffuse</name>
            </script>
          </material>
        </visual>
        <self_collide>0</self_collide>
        <enable_wind>0</enable_wind>
        <kinematic>0</kinematic>
      </link>
      <link name='front_left_wheel_steering_block'>
        <pose frame=''>1.03 0.5 0.32 1.5708 -0 0</pose>
        <inertial>
          <mass>1</mass>
          <inertia>
            <ixx>1</ixx>
            <ixy>0</ixy>
            <iyy>1</iyy>
            <ixz>0</ixz>
            <iyz>0</iyz>
            <izz>1</izz>
          </inertia>
          <pose frame=''>0 0 0 0 -0 0</pose>
        </inertial>
        <collision name='collision'>
          <geometry>
            <cylinder>
              <radius>0.05</radius>
              <length>0.01</length>
            </cylinder>
          </geometry>
          <max_contacts>10</max_contacts>
          <surface>
            <contact>
              <ode/>
            </contact>
            <bounce/>
            <friction>
              <torsional>
                <ode/>
              </torsional>
              <ode/>
            </friction>
          </surface>
        </collision>
        <self_collide>0</self_collide>
        <enable_wind>0</enable_wind>
        <kinematic>0</kinematic>
      </link>
      <link name='gas_pedal'>
        <pose frame=''>0.63 0.1 0.58 0 -0 0</pose>
        <gravity>0</gravity>
        <inertial>
          <mass>0.1</mass>
          <pose frame=''>0 0 0 0 -0 0</pose>
          <inertia>
            <ixx>0.01</ixx>
            <ixy>0</ixy>
            <ixz>0</ixz>
            <iyy>0.01</iyy>
            <iyz>0</iyz>
            <izz>0.01</izz>
          </inertia>
        </inertial>
        <collision name='gas_pedal_collision'>
          <pose frame=''>-0.0385 0 -0.086 3.14159 1.12559 3.14159</pose>
          <geometry>
            <box>
              <size>0.1069 0.077 0.01</size>
            </box>
          </geometry>
          <max_contacts>10</max_contacts>
          <surface>
            <contact>
              <ode/>
            </contact>
            <bounce/>
            <friction>
              <torsional>
                <ode/>
              </torsional>
              <ode/>
            </friction>
          </surface>
        </collision>
        <visual name='visual'>
          <pose frame=''>0 0 0 0 0 -1.5707</pose>
          <geometry>
            <mesh>
              <uri>model://polaris_ranger_ev/meshes/polaris.dae</uri>
              <submesh>
                <name>Pedal_Gas</name>
                <center>1</center>
              </submesh>
            </mesh>
          </geometry>
          <material>
            <script>
              <uri>model://polaris_ranger_ev/materials/scripts</uri>
              <uri>model://polaris_ranger_ev/materials/textures</uri>
              <name>Polaris/Diffuse</name>
            </script>
          </material>
        </visual>
        <self_collide>0</self_collide>
        <enable_wind>0</enable_wind>
        <kinematic>0</kinematic>
      </link>
      <link name='brake_pedal'>
        <gravity>0</gravity>
        <pose frame=''>0.64 0.27 0.58 0 -0 0</pose>
        <inertial>
          <mass>0.1</mass>
          <pose frame=''>0 0 0 0 -0 0</pose>
          <inertia>
            <ixx>0.01</ixx>
            <ixy>0</ixy>
            <ixz>0</ixz>
            <iyy>0.01</iyy>
            <iyz>0</iyz>
            <izz>0.01</izz>
          </inertia>
        </inertial>
        <collision name='brake_pedal_collision'>
          <pose frame=''>-0.04 0 -0.086 3.14159 1.14259 3.14159</pose>
          <geometry>
            <box>
              <size>0.063 0.08 0.01</size>
            </box>
          </geometry>
          <max_contacts>10</max_contacts>
          <surface>
            <contact>
              <ode/>
            </contact>
            <bounce/>
            <friction>
              <torsional>
                <ode/>
              </torsional>
              <ode/>
            </friction>
          </surface>
        </collision>
        <visual name='visual'>
          <pose frame=''>0 0 0 0 0 -1.5707</pose>
          <geometry>
            <mesh>
              <uri>model://polaris_ranger_ev/meshes/polaris.dae</uri>
              <submesh>
                <name>Pedal_brake</name>
                <center>1</center>
              </submesh>
            </mesh>
          </geometry>
          <material>
            <script>
              <uri>model://polaris_ranger_ev/materials/scripts</uri>
              <uri>model://polaris_ranger_ev/materials/textures</uri>
              <name>Polaris/Diffuse</name>
            </script>
          </material>
        </visual>
        <self_collide>0</self_collide>
        <enable_wind>0</enable_wind>
        <kinematic>0</kinematic>
      </link>
      <link name='steering_wheel'>
        <pose frame=''>0.34 0.3 1.29 0 -0.87 0</pose>
        <inertial>
          <mass>1</mass>
          <pose frame=''>-0.002 0 0 0 -0 0</pose>
          <inertia>
            <ixx>0.012</ixx>
            <ixy>0</ixy>
            <ixz>0</ixz>
            <iyy>0.012</iyy>
            <iyz>0</iyz>
            <izz>0.024</izz>
          </inertia>
        </inertial>
        <collision name='collision'>
          <pose frame=''>0 0 0 -0.69 -0 -1.5708</pose>
          <geometry>
            <mesh>
              <uri>model://polaris_ranger_ev/meshes/polaris.dae</uri>
              <submesh>
                <name>Steering_Wheel</name>
                <center>1</center>
              </submesh>
            </mesh>
          </geometry>
          <surface>
            <contact>
              <ode>
                <min_depth>0.003</min_depth>
              </ode>
            </contact>
            <bounce/>
            <friction>
              <torsional>
                <ode/>
              </torsional>
              <ode/>
            </friction>
          </surface>
          <max_contacts>10</max_contacts>
        </collision>
        <visual name='visual'>
          <pose frame=''>0 0 0 -0.69 -0 -1.5708</pose>
          <geometry>
            <mesh>
              <uri>model://polaris_ranger_ev/meshes/polaris.dae</uri>
              <submesh>
                <name>Steering_Wheel</name>
                <center>1</center>
              </submesh>
            </mesh>
          </geometry>
          <material>
            <script>
              <uri>model://polaris_ranger_ev/materials/scripts</uri>
              <uri>model://polaris_ranger_ev/materials/textures</uri>
              <name>Polaris/Diffuse</name>
            </script>
          </material>
        </visual>
        <self_collide>0</self_collide>
        <enable_wind>0</enable_wind>
        <kinematic>0</kinematic>
      </link>
      <link name='hand_brake'>
        <pose frame=''>0.53 0.07 1.05 0 -0 0</pose>
        <inertial>
          <mass>0.5</mass>
          <inertia>
            <ixx>0.1</ixx>
            <ixy>0</ixy>
            <ixz>0</ixz>
            <iyy>0.1</iyy>
            <iyz>0</iyz>
            <izz>0.05</izz>
          </inertia>
          <pose frame=''>0 0 0 0 -0 0</pose>
        </inertial>
        <collision name='hand_brake_collision'>
          <pose frame=''>0 0 0.05 -0.2 -0 -1.5708</pose>
          <geometry>
            <mesh>
              <uri>model://polaris_ranger_ev/meshes/polaris.dae</uri>
              <submesh>
                <name>E-Brake</name>
                <center>1</center>
              </submesh>
            </mesh>
          </geometry>
          <max_contacts>10</max_contacts>
          <surface>
            <contact>
              <ode/>
            </contact>
            <bounce/>
            <friction>
              <torsional>
                <ode/>
              </torsional>
              <ode/>
            </friction>
          </surface>
        </collision>
        <visual name='hand_brake_visual'>
          <pose frame=''>0 0 0.05 -0.2 -0 -1.5708</pose>
          <geometry>
            <mesh>
              <uri>model://polaris_ranger_ev/meshes/polaris.dae</uri>
              <submesh>
                <name>E-Brake</name>
                <center>1</center>
              </submesh>
            </mesh>
          </geometry>
          <material>
            <script>
              <uri>model://polaris_ranger_ev/materials/scripts</uri>
              <uri>model://polaris_ranger_ev/materials/textures</uri>
              <name>Polaris/Diffuse</name>
            </script>
          </material>
        </visual>
        <self_collide>0</self_collide>
        <enable_wind>0</enable_wind>
        <kinematic>0</kinematic>
      </link>
      <link name='FNR_switch'>
        <pose frame=''>0.56 -0.02 1.08 0 0.25 0</pose>
        <inertial>
          <mass>0.1</mass>
          <inertia>
            <ixx>0.1</ixx>
            <ixy>0</ixy>
            <ixz>0</ixz>
            <iyy>6e-05</iyy>
            <iyz>0</iyz>
            <izz>0.1</izz>
          </inertia>
          <pose frame=''>0 0 0 0 -0 0</pose>
        </inertial>
        <collision name='FNR_switch'>
          <geometry>
            <box>
              <size>0.02 0.04 0.08</size>
            </box>
          </geometry>
          <max_contacts>10</max_contacts>
          <surface>
            <contact>
              <ode/>
            </contact>
            <bounce/>
            <friction>
              <torsional>
                <ode/>
              </torsional>
              <ode/>
            </friction>
          </surface>
        </collision>
        <visual name='FNR_switch_F'>
          <transparency>0</transparency>
          <geometry>
            <box>
              <size>0.02 0.04 0.08</size>
            </box>
          </geometry>
          <material>
            <script>
              <uri>model://polaris_ranger_ev/materials/scripts</uri>
              <uri>model://polaris_ranger_ev/materials/textures</uri>
              <name>FNR_switch_F</name>
            </script>
          </material>
        </visual>
        <visual name='FNR_switch_R'>
          <transparency>1</transparency>
          <geometry>
            <box>
              <size>0.0199 0.0399 0.0799</size>
            </box>
          </geometry>
          <material>
            <script>
              <uri>model://polaris_ranger_ev/materials/scripts</uri>
              <uri>model://polaris_ranger_ev/materials/textures</uri>
              <name>FNR_switch_R</name>
            </script>
          </material>
        </visual>
        <self_collide>0</self_collide>
        <enable_wind>0</enable_wind>
        <kinematic>0</kinematic>
      </link>
      <joint name='front_left_steering_joint' type='revolute'>
        <child>front_left_wheel_steering_block</child>
        <parent>chassis</parent>
        <axis>
          <xyz>0 0 1</xyz>
          <limit>
            <lower>-0.8727</lower>
            <upper>0.8727</upper>
          </limit>
          <dynamics>
            <damping>50</damping>
            <spring_reference>0</spring_reference>
            <spring_stiffness>0</spring_stiffness>
          </dynamics>
          <use_parent_model_frame>1</use_parent_model_frame>
        </axis>
        <physics>
          <ode>
            <cfm_damping>1</cfm_damping>
            <limit>
              <cfm>0</cfm>
              <erp>0.9</erp>
            </limit>
          </ode>
        </physics>
      </joint>
      <joint name='front_left_wheel_joint' type='revolute'>
        <child>front_left_wheel</child>
        <parent>front_left_wheel_steering_block</parent>
        <axis>
          <xyz>0 1 0.05</xyz>
          <use_parent_model_frame>1</use_parent_model_frame>
          <limit>
            <lower>-1e+16</lower>
            <upper>1e+16</upper>
          </limit>
          <dynamics>
            <spring_reference>0</spring_reference>
            <spring_stiffness>0</spring_stiffness>
          </dynamics>
        </axis>
      </joint>
      <joint name='front_right_steering_joint' type='revolute'>
        <child>front_right_wheel_steering_block</child>
        <parent>chassis</parent>
        <axis>
          <xyz>0 0 1</xyz>
          <limit>
            <lower>-0.8727</lower>
            <upper>0.8727</upper>
          </limit>
          <dynamics>
            <damping>50</damping>
            <spring_reference>0</spring_reference>
            <spring_stiffness>0</spring_stiffness>
          </dynamics>
          <use_parent_model_frame>1</use_parent_model_frame>
        </axis>
        <physics>
          <ode>
            <cfm_damping>1</cfm_damping>
            <limit>
              <cfm>0</cfm>
              <erp>0.9</erp>
            </limit>
          </ode>
        </physics>
      </joint>
      <joint name='front_right_wheel_joint' type='revolute'>
        <child>front_right_wheel</child>
        <parent>front_right_wheel_steering_block</parent>
        <axis>
          <xyz>0 1 -0.05</xyz>
          <use_parent_model_frame>1</use_parent_model_frame>
          <limit>
            <lower>-1e+16</lower>
            <upper>1e+16</upper>
          </limit>
          <dynamics>
            <spring_reference>0</spring_reference>
            <spring_stiffness>0</spring_stiffness>
          </dynamics>
        </axis>
      </joint>
      <joint name='rear_left_wheel_joint' type='revolute'>
        <child>rear_left_wheel</child>
        <parent>chassis</parent>
        <axis>
          <xyz>0 1 0.05</xyz>
          <use_parent_model_frame>1</use_parent_model_frame>
          <limit>
            <lower>-1e+16</lower>
            <upper>1e+16</upper>
          </limit>
          <dynamics>
            <spring_reference>0</spring_reference>
            <spring_stiffness>0</spring_stiffness>
          </dynamics>
        </axis>
      </joint>
      <joint name='rear_right_wheel_joint' type='revolute'>
        <pose frame=''>0 0 -0.1 0 -0 0</pose>
        <child>rear_right_wheel</child>
        <parent>chassis</parent>
        <axis>
          <xyz>0 1 -0.05</xyz>
          <use_parent_model_frame>1</use_parent_model_frame>
          <limit>
            <lower>-1e+16</lower>
            <upper>1e+16</upper>
          </limit>
          <dynamics>
            <spring_reference>0</spring_reference>
            <spring_stiffness>0</spring_stiffness>
          </dynamics>
        </axis>
      </joint>
      <joint name='rear_differential_joint' type='revolute'>
        <child>rear_right_wheel</child>
        <parent>rear_left_wheel</parent>
        <axis>
          <xyz>0 1 0</xyz>
          <dynamics>
            <damping>70</damping>
            <spring_reference>0</spring_reference>
            <spring_stiffness>0</spring_stiffness>
          </dynamics>
          <use_parent_model_frame>1</use_parent_model_frame>
          <limit>
            <lower>-1e+16</lower>
            <upper>1e+16</upper>
          </limit>
        </axis>
        <physics>
          <ode>
            <erp>0</erp>
            <cfm>1000</cfm>
            <cfm_damping>1</cfm_damping>
            <limit>
              <cfm>0</cfm>
              <erp>0.2</erp>
            </limit>
          </ode>
        </physics>
      </joint>
      <joint name='gas_joint' type='prismatic'>
        <parent>chassis</parent>
        <child>gas_pedal</child>
        <axis>
          <xyz>1 0 -1</xyz>
          <limit>
            <lower>0</lower>
            <upper>0.08</upper>
          </limit>
          <dynamics>
            <damping>3</damping>
            <spring_reference>0</spring_reference>
            <spring_stiffness>0</spring_stiffness>
          </dynamics>
          <use_parent_model_frame>1</use_parent_model_frame>
        </axis>
        <physics>
          <ode>
            <cfm_damping>1</cfm_damping>
            <limit>
              <cfm>0</cfm>
              <erp>0.2</erp>
            </limit>
          </ode>
        </physics>
      </joint>
      <joint name='brake_joint' type='prismatic'>
        <parent>chassis</parent>
        <child>brake_pedal</child>
        <axis>
          <xyz>1 0 -0.6</xyz>
          <limit>
            <lower>0</lower>
            <upper>0.08</upper>
          </limit>
          <dynamics>
            <damping>3</damping>
            <spring_reference>0</spring_reference>
            <spring_stiffness>0</spring_stiffness>
          </dynamics>
          <use_parent_model_frame>1</use_parent_model_frame>
        </axis>
        <physics>
          <ode>
            <cfm_damping>1</cfm_damping>
            <limit>
              <cfm>0</cfm>
              <erp>0.2</erp>
            </limit>
          </ode>
        </physics>
      </joint>
      <joint name='steering_joint' type='revolute'>
        <pose frame=''>-0.002 0 0 0 -0 0</pose>
        <parent>chassis</parent>
        <child>steering_wheel</child>
        <axis>
          <xyz>-1 0 0.84365</xyz>
          <limit>
            <lower>-3.14</lower>
            <upper>3.14</upper>
          </limit>
          <dynamics>
            <damping>1</damping>
            <spring_reference>0</spring_reference>
            <spring_stiffness>0</spring_stiffness>
          </dynamics>
          <use_parent_model_frame>1</use_parent_model_frame>
        </axis>
        <physics>
          <ode>
            <cfm_damping>1</cfm_damping>
            <limit>
              <cfm>0</cfm>
              <erp>0.2</erp>
            </limit>
          </ode>
        </physics>
      </joint>
      <joint name='hand_brake_joint' type='revolute'>
        <parent>chassis</parent>
        <child>hand_brake</child>
        <axis>
          <xyz>0 -1 0</xyz>
          <limit>
            <lower>0</lower>
            <upper>0.6</upper>
          </limit>
          <dynamics>
            <damping>1</damping>
            <spring_reference>0</spring_reference>
            <spring_stiffness>0</spring_stiffness>
          </dynamics>
          <use_parent_model_frame>1</use_parent_model_frame>
        </axis>
        <physics>
          <ode>
            <cfm_damping>1</cfm_damping>
            <limit>
              <cfm>0</cfm>
              <erp>0.2</erp>
            </limit>
          </ode>
        </physics>
      </joint>
      <joint name='FNR_switch_joint' type='revolute'>
        <parent>chassis</parent>
        <child>FNR_switch</child>
        <axis>
          <xyz>0 -1 0</xyz>
          <limit>
            <lower>-0.3</lower>
            <upper>0.3</upper>
          </limit>
          <dynamics>
            <damping>0.01</damping>
            <spring_reference>0</spring_reference>
            <spring_stiffness>0</spring_stiffness>
          </dynamics>
          <use_parent_model_frame>1</use_parent_model_frame>
        </axis>
        <physics>
          <ode>
            <cfm_damping>1</cfm_damping>
            <limit>
              <cfm>0</cfm>
              <erp>0.2</erp>
            </limit>
          </ode>
        </physics>
      </joint>
      <pose frame=''>-4.72574 -2.19586 0 0 -0 0</pose>
    </model>
    <model name='prius_hybrid_sensors'>
      <link name='prius_hybrid::chassis'>
        <inertial>
          <mass>1326</mass>
          <pose frame=''>0 -0.266 0.48 0 -0 0</pose>
          <inertia>
            <ixx>2581.13</ixx>
            <ixy>0</ixy>
            <iyy>591.308</iyy>
            <ixz>0</ixz>
            <iyz>0</iyz>
            <izz>2681.95</izz>
          </inertia>
        </inertial>
        <visual name='chassis_visual'>
          <geometry>
            <mesh>
              <uri>model://prius_hybrid/meshes/Hybrid.obj</uri>
              <scale>0.01 0.01 0.01</scale>
              <submesh>
                <name>Hybrid</name>
                <center>0</center>
              </submesh>
            </mesh>
          </geometry>
        </visual>
        <visual name='interior_visual'>
          <geometry>
            <mesh>
              <uri>model://prius_hybrid/meshes/Hybrid.obj</uri>
              <scale>0.01 0.01 0.01</scale>
              <submesh>
                <name>Hybrid_Interior</name>
                <center>0</center>
              </submesh>
            </mesh>
          </geometry>
        </visual>
        <visual name='windows_visual'>
          <geometry>
            <mesh>
              <uri>model://prius_hybrid/meshes/Hybrid.obj</uri>
              <scale>0.01 0.01 0.01</scale>
              <submesh>
                <name>Hybrid_Windows</name>
                <center>0</center>
              </submesh>
            </mesh>
          </geometry>
        </visual>
        <collision name='prius_hybrid::chassis'>
          <pose frame=''>0 0.05 0.625 0 -0 0</pose>
          <geometry>
            <box>
              <size>1.7526 2.1 0.95</size>
            </box>
          </geometry>
          <max_contacts>10</max_contacts>
          <surface>
            <contact>
              <ode/>
            </contact>
            <bounce/>
            <friction>
              <torsional>
                <ode/>
              </torsional>
              <ode/>
            </friction>
          </surface>
        </collision>
        <collision name='front_bumper'>
          <pose frame=''>0 -2 0.458488 0 -0 0</pose>
          <geometry>
            <box>
              <size>1.33728 0.48 0.566691</size>
            </box>
          </geometry>
          <max_contacts>10</max_contacts>
          <surface>
            <contact>
              <ode/>
            </contact>
            <bounce/>
            <friction>
              <torsional>
                <ode/>
              </torsional>
              <ode/>
            </friction>
          </surface>
        </collision>
        <collision name='hood'>
          <pose frame=''>0 -1.90084 0.676305 0.341247 -0 0</pose>
          <geometry>
            <box>
              <size>1.59797 0.493107 0.265468</size>
            </box>
          </geometry>
          <max_contacts>10</max_contacts>
          <surface>
            <contact>
              <ode/>
            </contact>
            <bounce/>
            <friction>
              <torsional>
                <ode/>
              </torsional>
              <ode/>
            </friction>
          </surface>
        </collision>
        <collision name='windshield'>
          <pose frame=''>0 -0.875105 1.03227 0.335476 -0 0</pose>
          <geometry>
            <box>
              <size>1.16838 1.65425 0.272347</size>
            </box>
          </geometry>
          <max_contacts>10</max_contacts>
          <surface>
            <contact>
              <ode/>
            </contact>
            <bounce/>
            <friction>
              <torsional>
                <ode/>
              </torsional>
              <ode/>
            </friction>
          </surface>
        </collision>
        <collision name='top_front'>
          <pose frame=''>0 0.161236 1.38604 0.13503 -0 0</pose>
          <geometry>
            <box>
              <size>1.27915 0.625988 0.171868</size>
            </box>
          </geometry>
          <max_contacts>10</max_contacts>
          <surface>
            <contact>
              <ode/>
            </contact>
            <bounce/>
            <friction>
              <torsional>
                <ode/>
              </torsional>
              <ode/>
            </friction>
          </surface>
        </collision>
        <collision name='top_rear'>
          <pose frame=''>0 0.817696 1.36007 -0.068997 0 0</pose>
          <geometry>
            <box>
              <size>1.28513 0.771189 0.226557</size>
            </box>
          </geometry>
          <max_contacts>10</max_contacts>
          <surface>
            <contact>
              <ode/>
            </contact>
            <bounce/>
            <friction>
              <torsional>
                <ode/>
              </torsional>
              <ode/>
            </friction>
          </surface>
        </collision>
        <collision name='rear_window'>
          <pose frame=''>0 1.64053 1.17513 -0.262017 0 0</pose>
          <geometry>
            <box>
              <size>1.26785 1.11634 0.244286</size>
            </box>
          </geometry>
          <max_contacts>10</max_contacts>
          <surface>
            <contact>
              <ode/>
            </contact>
            <bounce/>
            <friction>
              <torsional>
                <ode/>
              </torsional>
              <ode/>
            </friction>
          </surface>
        </collision>
        <collision name='trunk'>
          <pose frame=''>0 1.63706 0.88818 0 -0 0</pose>
          <geometry>
            <box>
              <size>1.78806 1.13899 0.482746</size>
            </box>
          </geometry>
          <max_contacts>10</max_contacts>
          <surface>
            <contact>
              <ode/>
            </contact>
            <bounce/>
            <friction>
              <torsional>
                <ode/>
              </torsional>
              <ode/>
            </friction>
          </surface>
        </collision>
        <collision name='back_bumper'>
          <pose frame=''>0 2.05445 0.57787 0 -0 0</pose>
          <geometry>
            <box>
              <size>1.78165 0.512093 0.581427</size>
            </box>
          </geometry>
          <max_contacts>10</max_contacts>
          <surface>
            <contact>
              <ode/>
            </contact>
            <bounce/>
            <friction>
              <torsional>
                <ode/>
              </torsional>
              <ode/>
            </friction>
          </surface>
        </collision>
        <pose frame=''>0 0 0.03 0 -0 0</pose>
        <self_collide>0</self_collide>
        <enable_wind>0</enable_wind>
        <kinematic>0</kinematic>
      </link>
      <link name='prius_hybrid::steering_wheel'>
        <pose frame=''>0.357734 -0.627868 1.01824 -1.3021 0 0</pose>
        <inertial>
          <mass>1</mass>
          <inertia>
            <ixx>0.145833</ixx>
            <ixy>0</ixy>
            <ixz>0</ixz>
            <iyy>0.145833</iyy>
            <iyz>0</iyz>
            <izz>0.125</izz>
          </inertia>
          <pose frame=''>0 0 0 0 -0 0</pose>
        </inertial>
        <collision name='collision'>
          <geometry>
            <cylinder>
              <radius>0.178172</radius>
              <length>0.041845</length>
            </cylinder>
          </geometry>
          <surface>
            <contact>
              <ode>
                <min_depth>0.003</min_depth>
              </ode>
            </contact>
            <bounce/>
            <friction>
              <torsional>
                <ode/>
              </torsional>
              <ode/>
            </friction>
          </surface>
          <max_contacts>10</max_contacts>
        </collision>
        <visual name='visual'>
          <pose frame=''>0 0 0 1.3021 -0 0</pose>
          <geometry>
            <mesh>
              <uri>model://prius_hybrid/meshes/Hybrid.obj</uri>
              <scale>0.01 0.01 0.01</scale>
              <submesh>
                <name>Steering_Wheel</name>
                <center>1</center>
              </submesh>
            </mesh>
          </geometry>
        </visual>
        <self_collide>0</self_collide>
        <enable_wind>0</enable_wind>
        <kinematic>0</kinematic>
      </link>
      <link name='prius_hybrid::front_left_wheel'>
        <pose frame=''>0.76 -1.41 0.33 0 -0 0</pose>
        <inertial>
          <mass>11</mass>
          <inertia>
            <ixx>0.586312</ixx>
            <ixy>0</ixy>
            <iyy>0.335529</iyy>
            <ixz>0</ixz>
            <iyz>0</iyz>
            <izz>0.335529</izz>
          </inertia>
          <pose frame=''>0 0 0 0 -0 0</pose>
        </inertial>
        <visual name='visual'>
          <pose frame=''>0.04 0 0 0 -0 0</pose>
          <geometry>
            <mesh>
              <uri>model://prius_hybrid/meshes/Hybrid.obj</uri>
              <scale>0.01 0.01 0.01</scale>
              <submesh>
                <name>Wheel_Front_Left_</name>
                <center>1</center>
              </submesh>
            </mesh>
          </geometry>
        </visual>
        <collision name='collision'>
          <pose frame=''>0 0 0 3.14159 1.57079 3.14159</pose>
          <geometry>
            <sphere>
              <radius>0.31265</radius>
            </sphere>
          </geometry>
          <surface>
            <friction>
              <ode>
                <mu>0.9</mu>
                <mu2>0.9</mu2>
                <slip1>0</slip1>
                <slip2>0</slip2>
              </ode>
              <torsional>
                <ode/>
              </torsional>
            </friction>
            <contact>
              <ode>
                <min_depth>0.001</min_depth>
                <kp>1e+09</kp>
              </ode>
            </contact>
            <bounce/>
          </surface>
          <max_contacts>10</max_contacts>
        </collision>
        <self_collide>0</self_collide>
        <enable_wind>0</enable_wind>
        <kinematic>0</kinematic>
      </link>
      <link name='prius_hybrid::front_right_wheel'>
        <pose frame=''>-0.76 -1.41 0.33 0 -0 0</pose>
        <inertial>
          <mass>11</mass>
          <inertia>
            <ixx>0.586312</ixx>
            <ixy>0</ixy>
            <iyy>0.335529</iyy>
            <ixz>0</ixz>
            <iyz>0</iyz>
            <izz>0.335529</izz>
          </inertia>
          <pose frame=''>0 0 0 0 -0 0</pose>
        </inertial>
        <visual name='visual'>
          <pose frame=''>-0.04 0 0 0 -0 0</pose>
          <pose frame=''>0 0 0 0 -0 0</pose>
          <geometry>
            <mesh>
              <uri>model://prius_hybrid/meshes/Hybrid.obj</uri>
              <scale>0.01 0.01 0.01</scale>
              <submesh>
                <name>Wheel_Front_Right</name>
                <center>1</center>
              </submesh>
            </mesh>
          </geometry>
        </visual>
        <collision name='collision'>
          <pose frame=''>0 0 0 3.14159 1.57079 3.14159</pose>
          <geometry>
            <sphere>
              <radius>0.31265</radius>
            </sphere>
          </geometry>
          <surface>
            <friction>
              <ode>
                <mu>0.9</mu>
                <mu2>0.9</mu2>
                <slip1>0</slip1>
                <slip2>0</slip2>
              </ode>
              <torsional>
                <ode/>
              </torsional>
            </friction>
            <contact>
              <ode>
                <min_depth>0.001</min_depth>
                <kp>1e+09</kp>
              </ode>
            </contact>
            <bounce/>
          </surface>
          <max_contacts>10</max_contacts>
        </collision>
        <self_collide>0</self_collide>
        <enable_wind>0</enable_wind>
        <kinematic>0</kinematic>
      </link>
      <link name='prius_hybrid::rear_left_wheel'>
        <pose frame=''>0.786 1.45 0.33 0 -0 0</pose>
        <inertial>
          <mass>11</mass>
          <inertia>
            <ixx>0.586312</ixx>
            <ixy>0</ixy>
            <iyy>0.335529</iyy>
            <ixz>0</ixz>
            <iyz>0</iyz>
            <izz>0.335529</izz>
          </inertia>
          <pose frame=''>0 0 0 0 -0 0</pose>
        </inertial>
        <visual name='visual'>
          <pose frame=''>0.04 0 0 0 -0 0</pose>
          <geometry>
            <mesh>
              <uri>model://prius_hybrid/meshes/Hybrid.obj</uri>
              <scale>0.01 0.01 0.01</scale>
              <submesh>
                <name>Wheel_Front_Left_</name>
                <center>1</center>
              </submesh>
            </mesh>
          </geometry>
        </visual>
        <collision name='collision'>
          <pose frame=''>0 0 0 3.14159 1.57079 3.14159</pose>
          <geometry>
            <sphere>
              <radius>0.31265</radius>
            </sphere>
          </geometry>
          <surface>
            <friction>
              <ode>
                <mu>1.1</mu>
                <mu2>1.1</mu2>
                <slip1>0</slip1>
                <slip2>0</slip2>
              </ode>
              <torsional>
                <ode/>
              </torsional>
            </friction>
            <contact>
              <ode>
                <min_depth>0.001</min_depth>
                <kp>1e+09</kp>
              </ode>
            </contact>
            <bounce/>
          </surface>
          <max_contacts>10</max_contacts>
        </collision>
        <self_collide>0</self_collide>
        <enable_wind>0</enable_wind>
        <kinematic>0</kinematic>
      </link>
      <link name='prius_hybrid::rear_right_wheel'>
        <pose frame=''>-0.786 1.45 0.33 0 -0 0</pose>
        <inertial>
          <mass>11</mass>
          <inertia>
            <ixx>0.586312</ixx>
            <ixy>0</ixy>
            <iyy>0.335529</iyy>
            <ixz>0</ixz>
            <iyz>0</iyz>
            <izz>0.335529</izz>
          </inertia>
          <pose frame=''>0 0 0 0 -0 0</pose>
        </inertial>
        <visual name='visual'>
          <pose frame=''>-0.04 0 0 0 -0 0</pose>
          <geometry>
            <mesh>
              <uri>model://prius_hybrid/meshes/Hybrid.obj</uri>
              <scale>0.01 0.01 0.01</scale>
              <submesh>
                <name>Wheel_Front_Right</name>
                <center>1</center>
              </submesh>
            </mesh>
          </geometry>
        </visual>
        <collision name='collision'>
          <pose frame=''>0 0 0 3.14159 1.57079 3.14159</pose>
          <geometry>
            <sphere>
              <radius>0.31265</radius>
            </sphere>
          </geometry>
          <surface>
            <friction>
              <ode>
                <mu>1.1</mu>
                <mu2>1.1</mu2>
                <slip1>0</slip1>
                <slip2>0</slip2>
              </ode>
              <torsional>
                <ode/>
              </torsional>
            </friction>
            <contact>
              <ode>
                <min_depth>0.001</min_depth>
                <kp>1e+09</kp>
              </ode>
            </contact>
            <bounce/>
          </surface>
          <max_contacts>10</max_contacts>
        </collision>
        <self_collide>0</self_collide>
        <enable_wind>0</enable_wind>
        <kinematic>0</kinematic>
      </link>
      <joint name='prius_hybrid::front_left_combined_joint' type='universal'>
        <pose frame=''>0 0 0 -0.087266 0 0</pose>
        <child>prius_hybrid::front_left_wheel</child>
        <parent>prius_hybrid::chassis</parent>
        <axis>
          <xyz>0 0 1</xyz>
          <limit>
            <lower>-0.8727</lower>
            <upper>0.8727</upper>
          </limit>
          <use_parent_model_frame>0</use_parent_model_frame>
          <dynamics>
            <spring_reference>0</spring_reference>
            <spring_stiffness>0</spring_stiffness>
          </dynamics>
        </axis>
        <axis2>
          <xyz>1 0 0</xyz>
          <dynamics>
            <friction>18.0474</friction>
            <spring_reference>0</spring_reference>
            <spring_stiffness>0</spring_stiffness>
          </dynamics>
          <use_parent_model_frame>0</use_parent_model_frame>
        </axis2>
      </joint>
      <joint name='prius_hybrid::front_right_combined_joint' type='universal'>
        <pose frame=''>0 0 0 -0.087266 0 0</pose>
        <child>prius_hybrid::front_right_wheel</child>
        <parent>prius_hybrid::chassis</parent>
        <axis>
          <xyz>0 0 1</xyz>
          <limit>
            <lower>-0.8727</lower>
            <upper>0.8727</upper>
          </limit>
          <use_parent_model_frame>0</use_parent_model_frame>
          <dynamics>
            <spring_reference>0</spring_reference>
            <spring_stiffness>0</spring_stiffness>
          </dynamics>
        </axis>
        <axis2>
          <xyz>1 0 0</xyz>
          <dynamics>
            <friction>18.0474</friction>
            <spring_reference>0</spring_reference>
            <spring_stiffness>0</spring_stiffness>
          </dynamics>
          <use_parent_model_frame>0</use_parent_model_frame>
        </axis2>
      </joint>
      <link name='prius_hybrid::rear_axle'>
        <pose frame=''>0 1.45 0.33 0 -0 0</pose>
        <inertial>
          <mass>30</mass>
          <inertia>
            <ixx>0.084375</ixx>
            <ixy>0</ixy>
            <iyy>4.64581</iyy>
            <ixz>0</ixz>
            <iyz>0</iyz>
            <izz>4.64581</izz>
          </inertia>
          <pose frame=''>0 0 0 0 -0 0</pose>
        </inertial>
        <visual name='visual'>
          <pose frame=''>0 0 0 3.14159 1.57079 3.14159</pose>
          <geometry>
            <cylinder>
              <length>1.357</length>
              <radius>0.075</radius>
            </cylinder>
          </geometry>
          <material>
            <script>
              <name>Gazebo/Grey</name>
              <uri>file://media/materials/scripts/gazebo.material</uri>
            </script>
          </material>
        </visual>
        <self_collide>0</self_collide>
        <enable_wind>0</enable_wind>
        <kinematic>0</kinematic>
      </link>
      <joint name='prius_hybrid::rear_axle_joint' type='revolute'>
        <child>prius_hybrid::rear_axle</child>
        <parent>prius_hybrid::chassis</parent>
        <axis>
          <xyz>0 1 0</xyz>
          <limit>
            <lower>-0.0508906</lower>
            <upper>0.0508906</upper>
          </limit>
          <dynamics>
            <spring_stiffness>20000</spring_stiffness>
            <damping>2000</damping>
            <spring_reference>0</spring_reference>
          </dynamics>
          <use_parent_model_frame>0</use_parent_model_frame>
        </axis>
      </joint>
      <joint name='prius_hybrid::rear_left_wheel_joint' type='revolute'>
        <child>prius_hybrid::rear_left_wheel</child>
        <parent>prius_hybrid::rear_axle</parent>
        <axis>
          <xyz>1 0 0</xyz>
          <dynamics>
            <friction>12.0316</friction>
            <spring_reference>0</spring_reference>
            <spring_stiffness>0</spring_stiffness>
          </dynamics>
          <use_parent_model_frame>0</use_parent_model_frame>
          <limit>
            <lower>-1e+16</lower>
            <upper>1e+16</upper>
          </limit>
        </axis>
      </joint>
      <joint name='prius_hybrid::rear_right_wheel_joint' type='revolute'>
        <child>prius_hybrid::rear_right_wheel</child>
        <parent>prius_hybrid::rear_axle</parent>
        <axis>
          <xyz>1 0 0</xyz>
          <dynamics>
            <friction>12.0316</friction>
            <spring_reference>0</spring_reference>
            <spring_stiffness>0</spring_stiffness>
          </dynamics>
          <use_parent_model_frame>0</use_parent_model_frame>
          <limit>
            <lower>-1e+16</lower>
            <upper>1e+16</upper>
          </limit>
        </axis>
      </joint>
      <joint name='prius_hybrid::steering_joint' type='revolute'>
        <pose frame=''>-0.002 0 0 0 -0 0</pose>
        <parent>prius_hybrid::chassis</parent>
        <child>prius_hybrid::steering_wheel</child>
        <axis>
          <xyz>0 0.964095 0.265556</xyz>
          <limit>
            <lower>-7.85</lower>
            <upper>7.85</upper>
          </limit>
          <dynamics>
            <damping>1</damping>
            <spring_reference>0</spring_reference>
            <spring_stiffness>0</spring_stiffness>
          </dynamics>
          <use_parent_model_frame>1</use_parent_model_frame>
        </axis>
        <physics>
          <ode>
            <cfm_damping>1</cfm_damping>
            <limit>
              <cfm>0</cfm>
              <erp>0.2</erp>
            </limit>
          </ode>
        </physics>
      </joint>
      <joint name='sensor_joint' type='fixed'>
        <parent>prius_hybrid::chassis</parent>
        <child>sensors</child>
      </joint>
      <link name='sensors'>
        <sensor name='back_camera_sensor' type='camera'>
          <update_rate>30</update_rate>
          <camera name='back_camera'>
            <horizontal_fov>1.39626</horizontal_fov>
            <image>
              <width>800</width>
              <height>800</height>
              <format>R8G8B8</format>
            </image>
            <clip>
              <near>0.02</near>
              <far>300</far>
            </clip>
            <noise>
              <type>gaussian</type>
              <mean>0</mean>
              <stddev>0.007</stddev>
            </noise>
          </camera>
          <pose frame=''>0 1.45 1.4 0 0.05 1.5707</pose>
        </sensor>
        <sensor name='back_left_far_sonar_sensor' type='ray'>
          <ray>
            <scan>
              <horizontal>
                <samples>1</samples>
                <resolution>1</resolution>
                <min_angle>0</min_angle>
                <max_angle>0</max_angle>
              </horizontal>
              <vertical>
                <samples>1</samples>
                <min_angle>0</min_angle>
                <max_angle>0</max_angle>
              </vertical>
            </scan>
            <range>
              <min>0.2</min>
              <max>5</max>
              <resolution>0.1</resolution>
            </range>
          </ray>
          <always_on>0</always_on>
          <update_rate>5</update_rate>
          <pose frame=''>0.7 2.4 0.5 0 -0 1.5707</pose>
        </sensor>
        <sensor name='back_left_middle_sonar_sensor' type='ray'>
          <ray>
            <scan>
              <horizontal>
                <samples>1</samples>
                <resolution>1</resolution>
                <min_angle>0</min_angle>
                <max_angle>0</max_angle>
              </horizontal>
              <vertical>
                <samples>1</samples>
                <min_angle>0</min_angle>
                <max_angle>0</max_angle>
              </vertical>
            </scan>
            <range>
              <min>0.2</min>
              <max>5</max>
              <resolution>0.1</resolution>
            </range>
          </ray>
          <always_on>0</always_on>
          <update_rate>5</update_rate>
          <visualize>1</visualize>
          <pose frame=''>0.24 2.4 0.5 0 -0 1.5707</pose>
        </sensor>
        <sensor name='back_right_far_sonar_sensor' type='ray'>
          <ray>
            <scan>
              <horizontal>
                <samples>1</samples>
                <resolution>1</resolution>
                <min_angle>0</min_angle>
                <max_angle>0</max_angle>
              </horizontal>
              <vertical>
                <samples>1</samples>
                <min_angle>0</min_angle>
                <max_angle>0</max_angle>
              </vertical>
            </scan>
            <range>
              <min>0.2</min>
              <max>5</max>
              <resolution>0.1</resolution>
            </range>
          </ray>
          <always_on>0</always_on>
          <update_rate>5</update_rate>
          <visualize>1</visualize>
          <pose frame=''>-0.7 2.4 0.5 0 -0 1.5707</pose>
        </sensor>
        <sensor name='back_right_middle_sonar_sensor' type='ray'>
          <ray>
            <scan>
              <horizontal>
                <samples>1</samples>
                <resolution>1</resolution>
                <min_angle>0</min_angle>
                <max_angle>0</max_angle>
              </horizontal>
              <vertical>
                <samples>1</samples>
                <min_angle>0</min_angle>
                <max_angle>0</max_angle>
              </vertical>
            </scan>
            <range>
              <min>0.2</min>
              <max>5</max>
              <resolution>0.1</resolution>
            </range>
          </ray>
          <always_on>0</always_on>
          <update_rate>5</update_rate>
          <visualize>1</visualize>
          <pose frame=''>-0.24 2.4 0.5 0 -0 1.5707</pose>
        </sensor>
        <sensor name='center_laser_sensor' type='ray'>
          <ray>
            <scan>
              <horizontal>
                <samples>512</samples>
                <resolution>1</resolution>
                <min_angle>-3.14</min_angle>
                <max_angle>3.14</max_angle>
              </horizontal>
              <vertical>
                <samples>16</samples>
                <min_angle>-0.1</min_angle>
                <max_angle>-0.35</max_angle>
              </vertical>
            </scan>
            <range>
              <min>0.2</min>
              <max>30</max>
              <resolution>0.01</resolution>
            </range>
          </ray>
          <always_on>1</always_on>
          <update_rate>30</update_rate>
          <visualize>1</visualize>
          <pose frame=''>0 0.4 2 0 0 -1.5707</pose>
        </sensor>
        <sensor name='front_camera_sensor' type='camera'>
          <update_rate>30</update_rate>
          <camera name='front_camera'>
            <horizontal_fov>1.39626</horizontal_fov>
            <image>
              <width>800</width>
              <height>800</height>
              <format>R8G8B8</format>
            </image>
            <clip>
              <near>0.02</near>
              <far>300</far>
            </clip>
            <noise>
              <type>gaussian</type>
              <mean>0</mean>
              <stddev>0.007</stddev>
            </noise>
          </camera>
          <pose frame=''>0 -0.4 1.4 0 0.05 -1.5707</pose>
        </sensor>
        <sensor name='front_left_far_sonar_sensor' type='ray'>
          <ray>
            <scan>
              <horizontal>
                <samples>1</samples>
                <resolution>1</resolution>
                <min_angle>0</min_angle>
                <max_angle>0</max_angle>
              </horizontal>
              <vertical>
                <samples>1</samples>
                <min_angle>0</min_angle>
                <max_angle>0</max_angle>
              </vertical>
            </scan>
            <range>
              <min>0.2</min>
              <max>5</max>
              <resolution>0.1</resolution>
            </range>
          </ray>
          <always_on>0</always_on>
          <update_rate>5</update_rate>
          <visualize>1</visualize>
          <pose frame=''>0.7 -2.1 0.5 0 0 -1.5707</pose>
        </sensor>
        <sensor name='front_left_laser_sensor' type='ray'>
          <ray>
            <scan>
              <horizontal>
                <samples>640</samples>
                <resolution>1</resolution>
                <min_angle>-2.26889</min_angle>
                <max_angle>2.2689</max_angle>
              </horizontal>
              <vertical>
                <samples>1</samples>
                <min_angle>0</min_angle>
                <max_angle>0</max_angle>
              </vertical>
            </scan>
            <range>
              <min>0.2</min>
              <max>30</max>
              <resolution>0.01</resolution>
            </range>
          </ray>
          <always_on>1</always_on>
          <update_rate>30</update_rate>
          <visualize>1</visualize>
          <pose frame=''>1 -2.3 0.8 0 0.05 0</pose>
        </sensor>
        <sensor name='front_left_middle_sonar_sensor' type='ray'>
          <ray>
            <scan>
              <horizontal>
                <samples>1</samples>
                <resolution>1</resolution>
                <min_angle>0</min_angle>
                <max_angle>0</max_angle>
              </horizontal>
              <vertical>
                <samples>1</samples>
                <min_angle>0</min_angle>
                <max_angle>0</max_angle>
              </vertical>
            </scan>
            <range>
              <min>0.2</min>
              <max>5</max>
              <resolution>0.1</resolution>
            </range>
          </ray>
          <always_on>0</always_on>
          <update_rate>5</update_rate>
          <visualize>1</visualize>
          <pose frame=''>0.24 -2.3 0.5 0 0 -1.5707</pose>
        </sensor>
        <sensor name='front_right_far_sonar_sensor' type='ray'>
          <ray>
            <scan>
              <horizontal>
                <samples>1</samples>
                <resolution>1</resolution>
                <min_angle>0</min_angle>
                <max_angle>0</max_angle>
              </horizontal>
              <vertical>
                <samples>1</samples>
                <min_angle>0</min_angle>
                <max_angle>0</max_angle>
              </vertical>
            </scan>
            <range>
              <min>0.2</min>
              <max>5</max>
              <resolution>0.1</resolution>
            </range>
          </ray>
          <always_on>0</always_on>
          <update_rate>5</update_rate>
          <visualize>1</visualize>
          <pose frame=''>-0.7 -2.1 0.5 0 0 -1.5707</pose>
        </sensor>
        <sensor name='front_right_laser_sensor' type='ray'>
          <ray>
            <scan>
              <horizontal>
                <samples>640</samples>
                <resolution>1</resolution>
                <min_angle>-2.26889</min_angle>
                <max_angle>2.2689</max_angle>
              </horizontal>
              <vertical>
                <samples>1</samples>
                <min_angle>0</min_angle>
                <max_angle>0</max_angle>
              </vertical>
            </scan>
            <range>
              <min>0.2</min>
              <max>30</max>
              <resolution>0.01</resolution>
            </range>
          </ray>
          <always_on>1</always_on>
          <update_rate>30</update_rate>
          <visualize>1</visualize>
          <pose frame=''>-1 -2.3 0.8 -0 0.05 3.14</pose>
        </sensor>
        <sensor name='front_right_middle_sonar_sensor' type='ray'>
          <ray>
            <scan>
              <horizontal>
                <samples>1</samples>
                <resolution>1</resolution>
                <min_angle>0</min_angle>
                <max_angle>0</max_angle>
              </horizontal>
              <vertical>
                <samples>1</samples>
                <min_angle>0</min_angle>
                <max_angle>0</max_angle>
              </vertical>
            </scan>
            <range>
              <min>0.2</min>
              <max>5</max>
              <resolution>0.1</resolution>
            </range>
          </ray>
          <always_on>0</always_on>
          <update_rate>5</update_rate>
          <visualize>1</visualize>
          <pose frame=''>-0.24 -2.3 0.5 0 0 -1.5707</pose>
        </sensor>
        <sensor name='left_camera_sensor' type='camera'>
          <update_rate>30</update_rate>
          <camera name='left_camera'>
            <horizontal_fov>1.39626</horizontal_fov>
            <image>
              <width>800</width>
              <height>800</height>
              <format>R8G8B8</format>
            </image>
            <clip>
              <near>0.02</near>
              <far>300</far>
            </clip>
            <noise>
              <type>gaussian</type>
              <mean>0</mean>
              <stddev>0.007</stddev>
            </noise>
          </camera>
          <pose frame=''>1 -0.7 1 0 0.05 1</pose>
        </sensor>
        <sensor name='right_camera_sensor' type='camera'>
          <update_rate>30</update_rate>
          <camera name='right_camera'>
            <horizontal_fov>1.39626</horizontal_fov>
            <image>
              <width>800</width>
              <height>800</height>
              <format>R8G8B8</format>
            </image>
            <clip>
              <near>0.02</near>
              <far>300</far>
            </clip>
            <noise>
              <type>gaussian</type>
              <mean>0</mean>
              <stddev>0.007</stddev>
            </noise>
          </camera>
          <pose frame=''>-1 -0.7 1 0 0.05 2.1416</pose>
        </sensor>
        <sensor name='gps_sensor' type='gps'>
          <pose frame=''>0 0 0 0 -0 0</pose>
          <update_rate>10</update_rate>
          <always_on>1</always_on>
          <gps>
            <position_sensing>
              <horizontal>
                <noise type='gaussian_quantized'>
                  <mean>0</mean>
                  <stddev>1</stddev>
                  <bias_mean>3</bias_mean>
                  <bias_stddev>1</bias_stddev>
                  <precision>0.5</precision>
                </noise>
              </horizontal>
              <vertical>
                <noise type='gaussian_quantized'>
                  <mean>0</mean>
                  <stddev>1</stddev>
                  <bias_mean>3</bias_mean>
                  <bias_stddev>1</bias_stddev>
                  <precision>1</precision>
                </noise>
              </vertical>
            </position_sensing>
            <velocity_sensing>
              <horizontal>
                <noise type='gaussian_quantized'>
                  <mean>0</mean>
                  <stddev>0.1</stddev>
                  <bias_mean>0.1</bias_mean>
                  <bias_stddev>0.1</bias_stddev>
                  <precision>0.1</precision>
                </noise>
              </horizontal>
              <vertical>
                <noise type='gaussian_quantized'>
                  <mean>0</mean>
                  <stddev>0.2</stddev>
                  <bias_mean>0.2</bias_mean>
                  <bias_stddev>0.2</bias_stddev>
                  <precision>0.2</precision>
                </noise>
              </vertical>
            </velocity_sensing>
          </gps>
        </sensor>
        <sensor name='imu_sensor' type='imu'>
          <pose frame=''>0 0 0 0 -0 0</pose>
          <always_on>1</always_on>
          <update_rate>1000</update_rate>
          <imu/>
        </sensor>
        <self_collide>0</self_collide>
        <inertial>
          <pose frame=''>0 0 0 0 -0 0</pose>
          <inertia>
            <ixx>1</ixx>
            <ixy>0</ixy>
            <ixz>0</ixz>
            <iyy>1</iyy>
            <iyz>0</iyz>
            <izz>1</izz>
          </inertia>
          <mass>1</mass>
        </inertial>
        <enable_wind>0</enable_wind>
        <kinematic>0</kinematic>
      </link>
      <pose frame=''>-6.29145 8.79964 0 0 -0 0</pose>
    </model>
    <gui fullscreen='0'>
      <camera name='user_camera'>
        <pose frame=''>-32.7894 3.20654 9.50275 -0 0.327643 0.228196</pose>
        <view_controller>orbit</view_controller>
        <projection_type>perspective</projection_type>
      </camera>
    </gui>
  </world>
</sdf>
